Workbook

Sheet Alumnes
A1: AlumneID | B1: CodiQR | C1: Nom | D1: Cognoms | E1: CursGrup | F1: Actiu | G1: Observacions
A2: 1 | B2: FAX-A7K9Q2M4 | C2: Bayron Albeiro | D2: Alcázar Ramírez | E2: 1r d'ESO - Primer d'ESO | F2: =TRUE() -> TRUE
A3: 2 | B3: FAX-3ZP8L6R1 | C3: Yerai Alejandro | D3: Avila Mantuano | E3: 1r d'ESO - Primer d'ESO | F3: =TRUE() -> TRUE
A4: 3 | B4: FAX-M9F2A7XK | C4: Steve Sebastian | D4: Cabrera Matute | E4: 1r d'ESO - Primer d'ESO | F4: =TRUE() -> TRUE
A5: 4 | B5: FAX-8R4QZ1T6 | C5: Gerard | D5: Delgado Martínez | E5: 1r d'ESO - Primer d'ESO | F5: =TRUE() -> TRUE
A6: 5 | B6: FAX-L2M7A9P5 | C6: Danna Nicole | D6: Encinas Chávez | E6: 1r d'ESO - Primer d'ESO | F6: =TRUE() -> TRUE
A7: 6 | B7: FAX-Q6X8F3R9 | C7: Ainoa Sofia | D7: Falcon Garcia | E7: 1r d'ESO - Primer d'ESO | F7: =TRUE() -> TRUE
A8: 7 | B8: FAX-1A7ZKQ8M | C8: Anderson Mauricio | D8: Gutama Londoño | E8: 1r d'ESO - Primer d'ESO | F8: =TRUE() -> TRUE
A9: 8 | B9: FAX-P4F6R2X9 | C9: Keira Daniela | D9: Loor Sifuentes | E9: 1r d'ESO - Primer d'ESO | F9: =TRUE() -> TRUE
A10: 9 | B10: FAX-ZM8A5Q1K | C10: Jarett Esau | D10: Martínez Rivera | E10: 1r d'ESO - Primer d'ESO | F10: =TRUE() -> TRUE
A11: 10 | B11: FAX-7X2R9F6A | C11: Scarlet Charlotte | D11: Olalla Zuñiga | E11: 1r d'ESO - Primer d'ESO | F11: =TRUE() -> TRUE
A12: 11 | B12: FAX-KQ1M8Z4P | C12: Dylan Fabricio | D12: Palma Velásquez | E12: 1r d'ESO - Primer d'ESO | F12: =TRUE() -> TRUE
A13: 12 | B13: FAX-6A9X7R2F | C13: Thiago Anthony | D13: Pereira | E13: 1r d'ESO - Primer d'ESO | F13: =TRUE() -> TRUE
... A32: 31 | B32: FAX-7Q4P9X2A | C32: Anabella | D32: Rodríguez Coveña | E32: 4t d'ESO - Quart d'ESO | F32: =TRUE() -> TRUE

Sheet Registres
A1: RegistreID | B1: Timestamp | C1: Data | D1: Hora | E1: CodiQR | F1: AlumneID | G1: Nom | H1: Cognoms | I1: CursGrup | J1: Resultat | K1: Observacions

Sheet Resum Mensual
A1: RESUM MENSUAL D'ASSISTÈNCIA — Canvia el mes i any a les cel·les C2 i E2
A2: MES: | C2: 3 | D2: ANY: | E2: 2026
A4: ID | B4: Alumne | C4: Curs | D4: 1 | E4: 2 | F4: 3 | G4: 4 | H4: 5 | I4: 6 | J4: 7 | K4: 8 | L4: 9 | M4: 10 | N4: 11 | O4: 12 | P4: 13 | Q4: 14 | R4: 15 | S4: 16 | T4: 17 | U4: 18 | V4: 19 | W4: 20 | X4: 21 | Y4: 22 | Z4: 23 | AA4: 24 | AB4: 25 | AC4: 26 | AD4: 27 | AE4: 28 | AF4: 29 | AG4: 30 | AH4: 31 | AI4: TOTAL
A5: 1 | B5: Bayron Albeiro Alcázar Ramírez | C5: 1r ESO | D5: =IF(1<=DAY(EOMONTH(DATE($E$2,$C$2,1),0)),IF(SUMPRODUCT((DAY(Registres!C$2:C$500)=1)*(MONTH(Registres!C$2:C$500)=$C$2)*(YEAR(Registres!C$2:C$500)=$E$2)*(TEXT(Registres!F$2:F$500,"0")=TEXT($A5,"0")))>0,"✓",""),"") | E5: =IF(2<=DAY(EOMONTH(DATE($E$2,$C$2,1),0)),IF(SUMPRODUCT((DAY(Registres!C$2:C$500)=2)*(MONTH(Registres!C$2:C$500)=$C$2)*(YEAR(Registres!C$2:C$500)=$E$2)*(TEXT(Registres!F$2:F$500,"0")=TEXT($A5,"0")))>0,"✓",""),"") | F5: =IF(3<=DAY(EOMONTH(DATE($E$2,$C$2,1),0)),IF(SUMPRODUCT((DAY(Registres!C$2:C$500)=3)*(MONTH(Registres!C$2:C$500)=$C$2)*(YEAR(Registres!C$2:C$500)=$E$2)*(TEXT(Registres!F$2:F$500,"0")=TEXT($A5,"0")))>0,"✓",""),"") | G5: =IF(4<=DAY(EOMONTH(DATE($E$2,$C$2,1),0)),IF(SUMPRODUCT((DAY(Registres!C$2:C$500)=4)*(MONTH(Registres!C$2:C$500)=$C$2)*(YEAR(Registres!C$2:C$500)=$E$2)*(TEXT(Registres!F$2:F$500,"0")=TEXT($A5,"0")))>0,"✓",""),"") | H5: =IF(5<=DAY(EOMONTH(DATE($E$2,$C$2,1),0)),IF(SUMPRODUCT((DAY(Registres!C$2:C$500)=5)*(MONTH(Registres!C$2:C$500)=$C$2)*(YEAR(Registres!C$2:C$500)=$E$2)*(TEXT(Registres!F$2:F$500,"0")=TEXT($A5,"0")))>0,"✓",""),"") | I5: =IF(6<=DAY(EOMONTH(DATE($E$2,$C$2,1),0)),IF(SUMPRODUCT((DAY(Registres!C$2:C$500)=6)*(MONTH(Registres!C$2:C$500)=$C$2)*(YEAR(Registres!C$2:C$500)=$E$2)*(TEXT(Registres!F$2:F$500,"0")=TEXT($A5,"0")))>0,"✓",""),"") | J5: =IF(7<=DAY(EOMONTH(DATE($E$2,$C$2,1),0)),IF(SUMPRODUCT((DAY(Registres!C$2:C$500)=7)*(MONTH(Registres!C$2:C$500)=$C$2)*(YEAR(Registres!C$2:C$500)=$E$2)*(TEXT(Registres!F$2:F$500,"0")=TEXT($A5,"0")))>0,"✓",""),"") | K5: =IF(8<=DAY(EOMONTH(DATE($E$2,$C$2,1),0)),IF(SUMPRODUCT((DAY(Registres!C$2:C$500)=8)*(MONTH(Registres!C$2:C$500)=$C$2)*(YEAR(Registres!C$2:C$500)=$E$2)*(TEXT(Registres!F$2:F$500,"0")=TEXT($A5,"0")))>0,"✓",""),"") | L5: =IF(9<=DAY(EOMONTH(DATE($E$2,$C$2,1),0)),IF(SUMPRODUCT((DAY(Registres!C$2:C$500)=9)*(MONTH(Registres!C$2:C$500)=$C$2)*(YEAR(Registres!C$2:C$500)=$E$2)*(TEXT(Registres!F$2:F$500,"0")=TEXT($A5,"0")))>0,"✓",""),"") | M5: =IF(10<=DAY(EOMONTH(DATE($E$2,$C$2,1),0)),IF(SUMPRODUCT((DAY(Registres!C$2:C$500)=10)*(MONTH(Registres!C$2:C$500)=$C$2)*(YEAR(Registres!C$2:C$500)=$E$2)*(TEXT(Registres!F$2:F$500,"0")=TEXT($A5,"0")))>0,"✓",""),"") | N5: =IF(11<=DAY(EOMONTH(DATE($E$2,$C$2,1),0)),IF(SUMPRODUCT((DAY(Registres!C$2:C$500)=11)*(MONTH(Registres!C$2:C$500)=$C$2)*(YEAR(Registres!C$2:C$500)=$E$2)*(TEXT(Registres!F$2:F$500,"0")=TEXT($A5,"0")))>0,"✓",""),"") | O5: =IF(12<=DAY(EOMONTH(DATE($E$2,$C$2,1),0)),IF(SUMPRODUCT((DAY(Registres!C$2:C$500)=12)*(MONTH(Registres!C$2:C$500)=$C$2)*(YEAR(Registres!C$2:C$500)=$E$2)*(TEXT(Registres!F$2:F$500,"0")=TEXT($A5,"0")))>0,"✓",""),"") | P5: =IF(13<=DAY(EOMONTH(DATE($E$2,$C$2,1),0)),IF(SUMPRODUCT((DAY(Registres!C$2:C$500)=13)*(MONTH(Registres!C$2:C$500)=$C$2)*(YEAR(Registres!C$2:C$500)=$E$2)*(TEXT(Registres!F$2:F$500,"0")=TEXT($A5,"0")))>0,"✓",""),"") | Q5: =IF(14<=DAY(EOMONTH(DATE($E$2,$C$2,1),0)),IF(SUMPRODUCT((DAY(Registres!C$2:C$500)=14)*(MONTH(Registres!C$2:C$500)=$C$2)*(YEAR(Registres!C$2:C$500)=$E$2)*(TEXT(Registres!F$2:F$500,"0")=TEXT($A5,"0")))>0,"✓",""),"") | R5: =IF(15<=DAY(EOMONTH(DATE($E$2,$C$2,1),0)),IF(SUMPRODUCT((DAY(Registres!C$2:C$500)=15)*(MONTH(Registres!C$2:C$500)=$C$2)*(YEAR(Registres!C$2:C$500)=$E$2)*(TEXT(Registres!F$2:F$500,"0")=TEXT($A5,"0")))>0,"✓",""),"") | S5: =IF(16<=DAY(EOMONTH(DATE($E$2,$C$2,1),0)),IF(SUMPRODUCT((DAY(Registres!C$2:C$500)=16)*(MONTH(Registres!C$2:C$500)=$C$2)*(YEAR(Registres!C$2:C$500)=$E$2)*(TEXT(Registres!F$2:F$500,"0")=TEXT($A5,"0")))>0,"✓",""),"") | T5: =IF(17<=DAY(EOMONTH(DATE($E$2,$C$2,1),0)),IF(SUMPRODUCT((DAY(Registres!C$2:C$500)=17)*(MONTH(Registres!C$2:C$500)=$C$2)*(YEAR(Registres!C$2:C$500)=$E$2)*(TEXT(Registres!F$2:F$500,"0")=TEXT($A5,"0")))>0,"✓",""),"") | U5: =IF(18<=DAY(EOMONTH(DATE($E$2,$C$2,1),0)),IF(SUMPRODUCT((DAY(Registres!C$2:C$500)=18)*(MONTH(Registres!C$2:C$500)=$C$2)*(YEAR(Registres!C$2:C$500)=$E$2)*(TEXT(Registres!F$2:F$500,"0")=TEXT($A5,"0")))>0,"✓",""),"") | V5: =IF(19<=DAY(EOMONTH(DATE($E$2,$C$2,1),0)),IF(SUMPRODUCT((DAY(Registres!C$2:C$500)=19)*(MONTH(Registres!C$2:C$500)=$C$2)*(YEAR(Registres!C$2:C$500)=$E$2)*(TEXT(Registres!F$2:F$500,"0")=TEXT($A5,"0")))>0,"✓",""),"") | W5: =IF(20<=DAY(EOMONTH(DATE($E$2,$C$2,1),0)),IF(SUMPRODUCT((DAY(Registres!C$2:C$500)=20)*(MONTH(Registres!C$2:C$500)=$C$2)*(YEAR(Registres!C$2:C$500)=$E$2)*(TEXT(Registres!F$2:F$500,"0")=TEXT($A5,"0")))>0,"✓",""),"") | X5: =IF(21<=DAY(EOMONTH(DATE($E$2,$C$2,1),0)),IF(SUMPRODUCT((DAY(Registres!C$2:C$500)=21)*(MONTH(Registres!C$2:C$500)=$C$2)*(YEAR(Registres!C$2:C$500)=$E$2)*(TEXT(Registres!F$2:F$500,"0")=TEXT($A5,"0")))>0,"✓",""),"") | Y5: =IF(22<=DAY(EOMONTH(DATE($E$2,$C$2,1),0)),IF(SUMPRODUCT((DAY(Registres!C$2:C$500)=22)*(MONTH(Registres!C$2:C$500)=$C$2)*(YEAR(Registres!C$2:C$500)=$E$2)*(TEXT(Registres!F$2:F$500,"0")=TEXT($A5,"0")))>0,"✓",""),"") | Z5: =IF(23<=DAY(EOMONTH(DATE($E$2,$C$2,1),0)),IF(SUMPRODUCT((DAY(Registres!C$2:C$500)=23)*(MONTH(Registres!C$2:C$500)=$C$2)*(YEAR(Registres!C$2:C$500)=$E$2)*(TEXT(Registres!F$2:F$500,"0")=TEXT($A5,"0")))>0,"✓",""),"") | AA5: =IF(24<=DAY(EOMONTH(DATE($E$2,$C$2,1),0)),IF(SUMPRODUCT((DAY(Registres!C$2:C$500)=24)*(MONTH(Registres!C$2:C$500)=$C$2)*(YEAR(Registres!C$2:C$500)=$E$2)*(TEXT(Registres!F$2:F$500,"0")=TEXT($A5,"0")))>0,"✓",""),"") | AB5: =IF(25<=DAY(EOMONTH(DATE($E$2,$C$2,1),0)),IF(SUMPRODUCT((DAY(Registres!C$2:C$500)=25)*(MONTH(Registres!C$2:C$500)=$C$2)*(YEAR(Registres!C$2:C$500)=$E$2)*(TEXT(Registres!F$2:F$500,"0")=TEXT($A5,"0")))>0,"✓",""),"") | AC5: =IF(26<=DAY(EOMONTH(DATE($E$2,$C$2,1),0)),IF(SUMPRODUCT((DAY(Registres!C$2:C$500)=26)*(MONTH(Registres!C$2:C$500)=$C$2)*(YEAR(Registres!C$2:C$500)=$E$2)*(TEXT(Registres!F$2:F$500,"0")=TEXT($A5,"0")))>0,"✓",""),"") | AD5: =IF(27<=DAY(EOMONTH(DATE($E$2,$C$2,1),0)),IF(SUMPRODUCT((DAY(Registres!C$2:C$500)=27)*(MONTH(Registres!C$2:C$500)=$C$2)*(YEAR(Registres!C$2:C$500)=$E$2)*(TEXT(Registres!F$2:F$500,"0")=TEXT($A5,"0")))>0,"✓",""),"") | AE5: =IF(28<=DAY(EOMONTH(DATE($E$2,$C$2,1),0)),IF(SUMPRODUCT((DAY(Registres!C$2:C$500)=28)*(MONTH(Registres!C$2:C$500)=$C$2)*(YEAR(Registres!C$2:C$500)=$E$2)*(TEXT(Registres!F$2:F$500,"0")=TEXT($A5,"0")))>0,"✓",""),"") | AF5: =IF(29<=DAY(EOMONTH(DATE($E$2,$C$2,1),0)),IF(SUMPRODUCT((DAY(Registres!C$2:C$500)=29)*(MONTH(Registres!C$2:C$500)=$C$2)*(YEAR(Registres!C$2:C$500)=$E$2)*(TEXT(Registres!F$2:F$500,"0")=TEXT($A5,"0")))>0,"✓",""),"") | AG5: =IF(30<=DAY(EOMONTH(DATE($E$2,$C$2,1),0)),IF(SUMPRODUCT((DAY(Registres!C$2:C$500)=30)*(MONTH(Registres!C$2:C$500)=$C$2)*(YEAR(Registres!C$2:C$500)=$E$2)*(TEXT(Registres!F$2:F$500,"0")=TEXT($A5,"0")))>0,"✓",""),"") | AH5: =IF(31<=DAY(EOMONTH(DATE($E$2,$C$2,1),0)),IF(SUMPRODUCT((DAY(Registres!C$2:C$500)=31)*(MONTH(Registres!C$2:C$500)=$C$2)*(YEAR(Registres!C$2:C$500)=$E$2)*(TEXT(Registres!F$2:F$500,"0")=TEXT($A5,"0")))>0,"✓",""),"") | AI5: =COUNTIF(D5:AH5,"✓") -> 0
A6: 2 | B6: Yerai Alejandro Avila Mantuano | C6: 1r ESO | D6: =IF(1<=DAY(EOMONTH(DATE($E$2,$C$2,1),0)),IF(SUMPRODUCT((DAY(Registres!C$2:C$500)=1)*(MONTH(Registres!C$2:C$500)=$C$2)*(YEAR(Registres!C$2:C$500)=$E$2)*(TEXT(Registres!F$2:F$500,"0")=TEXT($A6,"0")))>0,"✓",""),"") | E6: =IF(2<=DAY(EOMONTH(DATE($E$2,$C$2,1),0)),IF(SUMPRODUCT((DAY(Registres!C$2:C$500)=2)*(MONTH(Registres!C$2:C$500)=$C$2)*(YEAR(Registres!C$2:C$500)=$E$2)*(TEXT(Registres!F$2:F$500,"0")=TEXT($A6,"0")))>0,"✓",""),"") | F6: =IF(3<=DAY(EOMONTH(DATE($E$2,$C$2,1),0)),IF(SUMPRODUCT((DAY(Registres!C$2:C$500)=3)*(MONTH(Registres!C$2:C$500)=$C$2)*(YEAR(Registres!C$2:C$500)=$E$2)*(TEXT(Registres!F$2:F$500,"0")=TEXT($A6,"0")))>0,"✓",""),"") | G6: =IF(4<=DAY(EOMONTH(DATE($E$2,$C$2,1),0)),IF(SUMPRODUCT((DAY(Registres!C$2:C$500)=4)*(MONTH(Registres!C$2:C$500)=$C$2)*(YEAR(Registres!C$2:C$500)=$E$2)*(TEXT(Registres!F$2:F$500,"0")=TEXT($A6,"0")))>0,"✓",""),"") | H6: =IF(5<=DAY(EOMONTH(DATE($E$2,$C$2,1),0)),IF(SUMPRODUCT((DAY(Registres!C$2:C$500)=5)*(MONTH(Registres!C$2:C$500)=$C$2)*(YEAR(Registres!C$2:C$500)=$E$2)*(TEXT(Registres!F$2:F$500,"0")=TEXT($A6,"0")))>0,"✓",""),"") | I6: =IF(6<=DAY(EOMONTH(DATE($E$2,$C$2,1),0)),IF(SUMPRODUCT((DAY(Registres!C$2:C$500)=6)*(MONTH(Registres!C$2:C$500)=$C$2)*(YEAR(Registres!C$2:C$500)=$E$2)*(TEXT(Registres!F$2:F$500,"0")=TEXT($A6,"0")))>0,"✓",""),"") | J6: =IF(7<=DAY(EOMONTH(DATE($E$2,$C$2,1),0)),IF(SUMPRODUCT((DAY(Registres!C$2:C$500)=7)*(MONTH(Registres!C$2:C$500)=$C$2)*(YEAR(Registres!C$2:C$500)=$E$2)*(TEXT(Registres!F$2:F$500,"0")=TEXT($A6,"0")))>0,"✓",""),"") | K6: =IF(8<=DAY(EOMONTH(DATE($E$2,$C$2,1),0)),IF(SUMPRODUCT((DAY(Registres!C$2:C$500)=8)*(MONTH(Registres!C$2:C$500)=$C$2)*(YEAR(Registres!C$2:C$500)=$E$2)*(TEXT(Registres!F$2:F$500,"0")=TEXT($A6,"0")))>0,"✓",""),"") | L6: =IF(9<=DAY(EOMONTH(DATE($E$2,$C$2,1),0)),IF(SUMPRODUCT((DAY(Registres!C$2:C$500)=9)*(MONTH(Registres!C$2:C$500)=$C$2)*(YEAR(Registres!C$2:C$500)=$E$2)*(TEXT(Registres!F$2:F$500,"0")=TEXT($A6,"0")))>0,"✓",""),"") | M6: =IF(10<=DAY(EOMONTH(DATE($E$2,$C$2,1),0)),IF(SUMPRODUCT((DAY(Registres!C$2:C$500)=10)*(MONTH(Registres!C$2:C$500)=$C$2)*(YEAR(Registres!C$2:C$500)=$E$2)*(TEXT(Registres!F$2:F$500,"0")=TEXT($A6,"0")))>0,"✓",""),"") | N6: =IF(11<=DAY(EOMONTH(DATE($E$2,$C$2,1),0)),IF(SUMPRODUCT((DAY(Registres!C$2:C$500)=11)*(MONTH(Registres!C$2:C$500)=$C$2)*(YEAR(Registres!C$2:C$500)=$E$2)*(TEXT(Registres!F$2:F$500,"0")=TEXT($A6,"0")))>0,"✓",""),"") | O6: =IF(12<=DAY(EOMONTH(DATE($E$2,$C$2,1),0)),IF(SUMPRODUCT((DAY(Registres!C$2:C$500)=12)*(MONTH(Registres!C$2:C$500)=$C$2)*(YEAR(Registres!C$2:C$500)=$E$2)*(TEXT(Registres!F$2:F$500,"0")=TEXT($A6,"0")))>0,"✓",""),"") | P6: =IF(13<=DAY(EOMONTH(DATE($E$2,$C$2,1),0)),IF(SUMPRODUCT((DAY(Registres!C$2:C$500)=13)*(MONTH(Registres!C$2:C$500)=$C$2)*(YEAR(Registres!C$2:C$500)=$E$2)*(TEXT(Registres!F$2:F$500,"0")=TEXT($A6,"0")))>0,"✓",""),"") | Q6: =IF(14<=DAY(EOMONTH(DATE($E$2,$C$2,1),0)),IF(SUMPRODUCT((DAY(Registres!C$2:C$500)=14)*(MONTH(Registres!C$2:C$500)=$C$2)*(YEAR(Registres!C$2:C$500)=$E$2)*(TEXT(Registres!F$2:F$500,"0")=TEXT($A6,"0")))>0,"✓",""),"") | R6: =IF(15<=DAY(EOMONTH(DATE($E$2,$C$2,1),0)),IF(SUMPRODUCT((DAY(Registres!C$2:C$500)=15)*(MONTH(Registres!C$2:C$500)=$C$2)*(YEAR(Registres!C$2:C$500)=$E$2)*(TEXT(Registres!F$2:F$500,"0")=TEXT($A6,"0")))>0,"✓",""),"") | S6: =IF(16<=DAY(EOMONTH(DATE($E$2,$C$2,1),0)),IF(SUMPRODUCT((DAY(Registres!C$2:C$500)=16)*(MONTH(Registres!C$2:C$500)=$C$2)*(YEAR(Registres!C$2:C$500)=$E$2)*(TEXT(Registres!F$2:F$500,"0")=TEXT($A6,"0")))>0,"✓",""),"") | T6: =IF(17<=DAY(EOMONTH(DATE($E$2,$C$2,1),0)),IF(SUMPRODUCT((DAY(Registres!C$2:C$500)=17)*(MONTH(Registres!C$2:C$500)=$C$2)*(YEAR(Registres!C$2:C$500)=$E$2)*(TEXT(Registres!F$2:F$500,"0")=TEXT($A6,"0")))>0,"✓",""),"") | U6: =IF(18<=DAY(EOMONTH(DATE($E$2,$C$2,1),0)),IF(SUMPRODUCT((DAY(Registres!C$2:C$500)=18)*(MONTH(Registres!C$2:C$500)=$C$2)*(YEAR(Registres!C$2:C$500)=$E$2)*(TEXT(Registres!F$2:F$500,"0")=TEXT($A6,"0")))>0,"✓",""),"") | V6: =IF(19<=DAY(EOMONTH(DATE($E$2,$C$2,1),0)),IF(SUMPRODUCT((DAY(Registres!C$2:C$500)=19)*(MONTH(Registres!C$2:C$500)=$C$2)*(YEAR(Registres!C$2:C$500)=$E$2)*(TEXT(Registres!F$2:F$500,"0")=TEXT($A6,"0")))>0,"✓",""),"") | W6: =IF(20<=DAY(EOMONTH(DATE($E$2,$C$2,1),0)),IF(SUMPRODUCT((DAY(Registres!C$2:C$500)=20)*(MONTH(Registres!C$2:C$500)=$C$2)*(YEAR(Registres!C$2:C$500)=$E$2)*(TEXT(Registres!F$2:F$500,"0")=TEXT($A6,"0")))>0,"✓",""),"") | X6: =IF(21<=DAY(EOMONTH(DATE($E$2,$C$2,1),0)),IF(SUMPRODUCT((DAY(Registres!C$2:C$500)=21)*(MONTH(Registres!C$2:C$500)=$C$2)*(YEAR(Registres!C$2:C$500)=$E$2)*(TEXT(Registres!F$2:F$500,"0")=TEXT($A6,"0")))>0,"✓",""),"") | Y6: =IF(22<=DAY(EOMONTH(DATE($E$2,$C$2,1),0)),IF(SUMPRODUCT((DAY(Registres!C$2:C$500)=22)*(MONTH(Registres!C$2:C$500)=$C$2)*(YEAR(Registres!C$2:C$500)=$E$2)*(TEXT(Registres!F$2:F$500,"0")=TEXT($A6,"0")))>0,"✓",""),"") | Z6: =IF(23<=DAY(EOMONTH(DATE($E$2,$C$2,1),0)),IF(SUMPRODUCT((DAY(Registres!C$2:C$500)=23)*(MONTH(Registres!C$2:C$500)=$C$2)*(YEAR(Registres!C$2:C$500)=$E$2)*(TEXT(Registres!F$2:F$500,"0")=TEXT($A6,"0")))>0,"✓",""),"") | AA6: =IF(24<=DAY(EOMONTH(DATE($E$2,$C$2,1),0)),IF(SUMPRODUCT((DAY(Registres!C$2:C$500)=24)*(MONTH(Registres!C$2:C$500)=$C$2)*(YEAR(Registres!C$2:C$500)=$E$2)*(TEXT(Registres!F$2:F$500,"0")=TEXT($A6,"0")))>0,"✓",""),"") | AB6: =IF(25<=DAY(EOMONTH(DATE($E$2,$C$2,1),0)),IF(SUMPRODUCT((DAY(Registres!C$2:C$500)=25)*(MONTH(Registres!C$2:C$500)=$C$2)*(YEAR(Registres!C$2:C$500)=$E$2)*(TEXT(Registres!F$2:F$500,"0")=TEXT($A6,"0")))>0,"✓",""),"") | AC6: =IF(26<=DAY(EOMONTH(DATE($E$2,$C$2,1),0)),IF(SUMPRODUCT((DAY(Registres!C$2:C$500)=26)*(MONTH(Registres!C$2:C$500)=$C$2)*(YEAR(Registres!C$2:C$500)=$E$2)*(TEXT(Registres!F$2:F$500,"0")=TEXT($A6,"0")))>0,"✓",""),"") | AD6: =IF(27<=DAY(EOMONTH(DATE($E$2,$C$2,1),0)),IF(SUMPRODUCT((DAY(Registres!C$2:C$500)=27)*(MONTH(Registres!C$2:C$500)=$C$2)*(YEAR(Registres!C$2:C$500)=$E$2)*(TEXT(Registres!F$2:F$500,"0")=TEXT($A6,"0")))>0,"✓",""),"") | AE6: =IF(28<=DAY(EOMONTH(DATE($E$2,$C$2,1),0)),IF(SUMPRODUCT((DAY(Registres!C$2:C$500)=28)*(MONTH(Registres!C$2:C$500)=$C$2)*(YEAR(Registres!C$2:C$500)=$E$2)*(TEXT(Registres!F$2:F$500,"0")=TEXT($A6,"0")))>0,"✓",""),"") | AF6: =IF(29<=DAY(EOMONTH(DATE($E$2,$C$2,1),0)),IF(SUMPRODUCT((DAY(Registres!C$2:C$500)=29)*(MONTH(Registres!C$2:C$500)=$C$2)*(YEAR(Registres!C$2:C$500)=$E$2)*(TEXT(Registres!F$2:F$500,"0")=TEXT($A6,"0")))>0,"✓",""),"") | AG6: =IF(30<=DAY(EOMONTH(DATE($E$2,$C$2,1),0)),IF(SUMPRODUCT((DAY(Registres!C$2:C$500)=30)*(MONTH(Registres!C$2:C$500)=$C$2)*(YEAR(Registres!C$2:C$500)=$E$2)*(TEXT(Registres!F$2:F$500,"0")=TEXT($A6,"0")))>0,"✓",""),"") | AH6: =IF(31<=DAY(EOMONTH(DATE($E$2,$C$2,1),0)),IF(SUMPRODUCT((DAY(Registres!C$2:C$500)=31)*(MONTH(Registres!C$2:C$500)=$C$2)*(YEAR(Registres!C$2:C$500)=$E$2)*(TEXT(Registres!F$2:F$500,"0")=TEXT($A6,"0")))>0,"✓",""),"") | AI6: =COUNTIF(D6:AH6,"✓") -> 0
A7: 3 | B7: Steve Sebastian Cabrera Matute | C7: 1r ESO | D7: =IF(1<=DAY(EOMONTH(DATE($E$2,$C$2,1),0)),IF(SUMPRODUCT((DAY(Registres!C$2:C$500)=1)*(MONTH(Registres!C$2:C$500)=$C$2)*(YEAR(Registres!C$2:C$500)=$E$2)*(TEXT(Registres!F$2:F$500,"0")=TEXT($A7,"0")))>0,"✓",""),"") | E7: =IF(2<=DAY(EOMONTH(DATE($E$2,$C$2,1),0)),IF(SUMPRODUCT((DAY(Registres!C$2:C$500)=2)*(MONTH(Registres!C$2:C$500)=$C$2)*(YEAR(Registres!C$2:C$500)=$E$2)*(TEXT(Registres!F$2:F$500,"0")=TEXT($A7,"0")))>0,"✓",""),"") | F7: =IF(3<=DAY(EOMONTH(DATE($E$2,$C$2,1),0)),IF(SUMPRODUCT((DAY(Registres!C$2:C$500)=3)*(MONTH(Registres!C$2:C$500)=$C$2)*(YEAR(Registres!C$2:C$500)=$E$2)*(TEXT(Registres!F$2:F$500,"0")=TEXT($A7,"0")))>0,"✓",""),"") | G7: =IF(4<=DAY(EOMONTH(DATE($E$2,$C$2,1),0)),IF(SUMPRODUCT((DAY(Registres!C$2:C$500)=4)*(MONTH(Registres!C$2:C$500)=$C$2)*(YEAR(Registres!C$2:C$500)=$E$2)*(TEXT(Registres!F$2:F$500,"0")=TEXT($A7,"0")))>0,"✓",""),"") | H7: =IF(5<=DAY(EOMONTH(DATE($E$2,$C$2,1),0)),IF(SUMPRODUCT((DAY(Registres!C$2:C$500)=5)*(MONTH(Registres!C$2:C$500)=$C$2)*(YEAR(Registres!C$2:C$500)=$E$2)*(TEXT(Registres!F$2:F$500,"0")=TEXT($A7,"0")))>0,"✓",""),"") | I7: =IF(6<=DAY(EOMONTH(DATE($E$2,$C$2,1),0)),IF(SUMPRODUCT((DAY(Registres!C$2:C$500)=6)*(MONTH(Registres!C$2:C$500)=$C$2)*(YEAR(Registres!C$2:C$500)=$E$2)*(TEXT(Registres!F$2:F$500,"0")=TEXT($A7,"0")))>0,"✓",""),"") | J7: =IF(7<=DAY(EOMONTH(DATE($E$2,$C$2,1),0)),IF(SUMPRODUCT((DAY(Registres!C$2:C$500)=7)*(MONTH(Registres!C$2:C$500)=$C$2)*(YEAR(Registres!C$2:C$500)=$E$2)*(TEXT(Registres!F$2:F$500,"0")=TEXT($A7,"0")))>0,"✓",""),"") | K7: =IF(8<=DAY(EOMONTH(DATE($E$2,$C$2,1),0)),IF(SUMPRODUCT((DAY(Registres!C$2:C$500)=8)*(MONTH(Registres!C$2:C$500)=$C$2)*(YEAR(Registres!C$2:C$500)=$E$2)*(TEXT(Registres!F$2:F$500,"0")=TEXT($A7,"0")))>0,"✓",""),"") | L7: =IF(9<=DAY(EOMONTH(DATE($E$2,$C$2,1),0)),IF(SUMPRODUCT((DAY(Registres!C$2:C$500)=9)*(MONTH(Registres!C$2:C$500)=$C$2)*(YEAR(Registres!C$2:C$500)=$E$2)*(TEXT(Registres!F$2:F$500,"0")=TEXT($A7,"0")))>0,"✓",""),"") | M7: =IF(10<=DAY(EOMONTH(DATE($E$2,$C$2,1),0)),IF(SUMPRODUCT((DAY(Registres!C$2:C$500)=10)*(MONTH(Registres!C$2:C$500)=$C$2)*(YEAR(Registres!C$2:C$500)=$E$2)*(TEXT(Registres!F$2:F$500,"0")=TEXT($A7,"0")))>0,"✓",""),"") | N7: =IF(11<=DAY(EOMONTH(DATE($E$2,$C$2,1),0)),IF(SUMPRODUCT((DAY(Registres!C$2:C$500)=11)*(MONTH(Registres!C$2:C$500)=$C$2)*(YEAR(Registres!C$2:C$500)=$E$2)*(TEXT(Registres!F$2:F$500,"0")=TEXT($A7,"0")))>0,"✓",""),"") | O7: =IF(12<=DAY(EOMONTH(DATE($E$2,$C$2,1),0)),IF(SUMPRODUCT((DAY(Registres!C$2:C$500)=12)*(MONTH(Registres!C$2:C$500)=$C$2)*(YEAR(Registres!C$2:C$500)=$E$2)*(TEXT(Registres!F$2:F$500,"0")=TEXT($A7,"0")))>0,"✓",""),"") | P7: =IF(13<=DAY(EOMONTH(DATE($E$2,$C$2,1),0)),IF(SUMPRODUCT((DAY(Registres!C$2:C$500)=13)*(MONTH(Registres!C$2:C$500)=$C$2)*(YEAR(Registres!C$2:C$500)=$E$2)*(TEXT(Registres!F$2:F$500,"0")=TEXT($A7,"0")))>0,"✓",""),"") | Q7: =IF(14<=DAY(EOMONTH(DATE($E$2,$C$2,1),0)),IF(SUMPRODUCT((DAY(Registres!C$2:C$500)=14)*(MONTH(Registres!C$2:C$500)=$C$2)*(YEAR(Registres!C$2:C$500)=$E$2)*(TEXT(Registres!F$2:F$500,"0")=TEXT($A7,"0")))>0,"✓",""),"") | R7: =IF(15<=DAY(EOMONTH(DATE($E$2,$C$2,1),0)),IF(SUMPRODUCT((DAY(Registres!C$2:C$500)=15)*(MONTH(Registres!C$2:C$500)=$C$2)*(YEAR(Registres!C$2:C$500)=$E$2)*(TEXT(Registres!F$2:F$500,"0")=TEXT($A7,"0")))>0,"✓",""),"") | S7: =IF(16<=DAY(EOMONTH(DATE($E$2,$C$2,1),0)),IF(SUMPRODUCT((DAY(Registres!C$2:C$500)=16)*(MONTH(Registres!C$2:C$500)=$C$2)*(YEAR(Registres!C$2:C$500)=$E$2)*(TEXT(Registres!F$2:F$500,"0")=TEXT($A7,"0")))>0,"✓",""),"") | T7: =IF(17<=DAY(EOMONTH(DATE($E$2,$C$2,1),0)),IF(SUMPRODUCT((DAY(Registres!C$2:C$500)=17)*(MONTH(Registres!C$2:C$500)=$C$2)*(YEAR(Registres!C$2:C$500)=$E$2)*(TEXT(Registres!F$2:F$500,"0")=TEXT($A7,"0")))>0,"✓",""),"") | U7: =IF(18<=DAY(EOMONTH(DATE($E$2,$C$2,1),0)),IF(SUMPRODUCT((DAY(Registres!C$2:C$500)=18)*(MONTH(Registres!C$2:C$500)=$C$2)*(YEAR(Registres!C$2:C$500)=$E$2)*(TEXT(Registres!F$2:F$500,"0")=TEXT($A7,"0")))>0,"✓",""),"") | V7: =IF(19<=DAY(EOMONTH(DATE($E$2,$C$2,1),0)),IF(SUMPRODUCT((DAY(Registres!C$2:C$500)=19)*(MONTH(Registres!C$2:C$500)=$C$2)*(YEAR(Registres!C$2:C$500)=$E$2)*(TEXT(Registres!F$2:F$500,"0")=TEXT($A7,"0")))>0,"✓",""),"") | W7: =IF(20<=DAY(EOMONTH(DATE($E$2,$C$2,1),0)),IF(SUMPRODUCT((DAY(Registres!C$2:C$500)=20)*(MONTH(Registres!C$2:C$500)=$C$2)*(YEAR(Registres!C$2:C$500)=$E$2)*(TEXT(Registres!F$2:F$500,"0")=TEXT($A7,"0")))>0,"✓",""),"") | X7: =IF(21<=DAY(EOMONTH(DATE($E$2,$C$2,1),0)),IF(SUMPRODUCT((DAY(Registres!C$2:C$500)=21)*(MONTH(Registres!C$2:C$500)=$C$2)*(YEAR(Registres!C$2:C$500)=$E$2)*(TEXT(Registres!F$2:F$500,"0")=TEXT($A7,"0")))>0,"✓",""),"") | Y7: =IF(22<=DAY(EOMONTH(DATE($E$2,$C$2,1),0)),IF(SUMPRODUCT((DAY(Registres!C$2:C$500)=22)*(MONTH(Registres!C$2:C$500)=$C$2)*(YEAR(Registres!C$2:C$500)=$E$2)*(TEXT(Registres!F$2:F$500,"0")=TEXT($A7,"0")))>0,"✓",""),"") | Z7: =IF(23<=DAY(EOMONTH(DATE($E$2,$C$2,1),0)),IF(SUMPRODUCT((DAY(Registres!C$2:C$500)=23)*(MONTH(Registres!C$2:C$500)=$C$2)*(YEAR(Registres!C$2:C$500)=$E$2)*(TEXT(Registres!F$2:F$500,"0")=TEXT($A7,"0")))>0,"✓",""),"") | AA7: =IF(24<=DAY(EOMONTH(DATE($E$2,$C$2,1),0)),IF(SUMPRODUCT((DAY(Registres!C$2:C$500)=24)*(MONTH(Registres!C$2:C$500)=$C$2)*(YEAR(Registres!C$2:C$500)=$E$2)*(TEXT(Registres!F$2:F$500,"0")=TEXT($A7,"0")))>0,"✓",""),"") | AB7: =IF(25<=DAY(EOMONTH(DATE($E$2,$C$2,1),0)),IF(SUMPRODUCT((DAY(Registres!C$2:C$500)=25)*(MONTH(Registres!C$2:C$500)=$C$2)*(YEAR(Registres!C$2:C$500)=$E$2)*(TEXT(Registres!F$2:F$500,"0")=TEXT($A7,"0")))>0,"✓",""),"") | AC7: =IF(26<=DAY(EOMONTH(DATE($E$2,$C$2,1),0)),IF(SUMPRODUCT((DAY(Registres!C$2:C$500)=26)*(MONTH(Registres!C$2:C$500)=$C$2)*(YEAR(Registres!C$2:C$500)=$E$2)*(TEXT(Registres!F$2:F$500,"0")=TEXT($A7,"0")))>0,"✓",""),"") | AD7: =IF(27<=DAY(EOMONTH(DATE($E$2,$C$2,1),0)),IF(SUMPRODUCT((DAY(Registres!C$2:C$500)=27)*(MONTH(Registres!C$2:C$500)=$C$2)*(YEAR(Registres!C$2:C$500)=$E$2)*(TEXT(Registres!F$2:F$500,"0")=TEXT($A7,"0")))>0,"✓",""),"") | AE7: =IF(28<=DAY(EOMONTH(DATE($E$2,$C$2,1),0)),IF(SUMPRODUCT((DAY(Registres!C$2:C$500)=28)*(MONTH(Registres!C$2:C$500)=$C$2)*(YEAR(Registres!C$2:C$500)=$E$2)*(TEXT(Registres!F$2:F$500,"0")=TEXT($A7,"0")))>0,"✓",""),"") | AF7: =IF(29<=DAY(EOMONTH(DATE($E$2,$C$2,1),0)),IF(SUMPRODUCT((DAY(Registres!C$2:C$500)=29)*(MONTH(Registres!C$2:C$500)=$C$2)*(YEAR(Registres!C$2:C$500)=$E$2)*(TEXT(Registres!F$2:F$500,"0")=TEXT($A7,"0")))>0,"✓",""),"") | AG7: =IF(30<=DAY(EOMONTH(DATE($E$2,$C$2,1),0)),IF(SUMPRODUCT((DAY(Registres!C$2:C$500)=30)*(MONTH(Registres!C$2:C$500)=$C$2)*(YEAR(Registres!C$2:C$500)=$E$2)*(TEXT(Registres!F$2:F$500,"0")=TEXT($A7,"0")))>0,"✓",""),"") | AH7: =IF(31<=DAY(EOMONTH(DATE($E$2,$C$2,1),0)),IF(SUMPRODUCT((DAY(Registres!C$2:C$500)=31)*(MONTH(Registres!C$2:C$500)=$C$2)*(YEAR(Registres!C$2:C$500)=$E$2)*(TEXT(Registres!F$2:F$500,"0")=TEXT($A7,"0")))>0,"✓",""),"") | AI7: =COUNTIF(D7:AH7,"✓") -> 0
A8: 4 | B8: Gerard Delgado Martínez | C8: 1r ESO | D8: =IF(1<=DAY(EOMONTH(DATE($E$2,$C$2,1),0)),IF(SUMPRODUCT((DAY(Registres!C$2:C$500)=1)*(MONTH(Registres!C$2:C$500)=$C$2)*(YEAR(Registres!C$2:C$500)=$E$2)*(TEXT(Registres!F$2:F$500,"0")=TEXT($A8,"0")))>0,"✓",""),"") | E8: =IF(2<=DAY(EOMONTH(DATE($E$2,$C$2,1),0)),IF(SUMPRODUCT((DAY(Registres!C$2:C$500)=2)*(MONTH(Registres!C$2:C$500)=$C$2)*(YEAR(Registres!C$2:C$500)=$E$2)*(TEXT(Registres!F$2:F$500,"0")=TEXT($A8,"0")))>0,"✓",""),"") | F8: =IF(3<=DAY(EOMONTH(DATE($E$2,$C$2,1),0)),IF(SUMPRODUCT((DAY(Registres!C$2:C$500)=3)*(MONTH(Registres!C$2:C$500)=$C$2)*(YEAR(Registres!C$2:C$500)=$E$2)*(TEXT(Registres!F$2:F$500,"0")=TEXT($A8,"0")))>0,"✓",""),"") | G8: =IF(4<=DAY(EOMONTH(DATE($E$2,$C$2,1),0)),IF(SUMPRODUCT((DAY(Registres!C$2:C$500)=4)*(MONTH(Registres!C$2:C$500)=$C$2)*(YEAR(Registres!C$2:C$500)=$E$2)*(TEXT(Registres!F$2:F$500,"0")=TEXT($A8,"0")))>0,"✓",""),"") | H8: =IF(5<=DAY(EOMONTH(DATE($E$2,$C$2,1),0)),IF(SUMPRODUCT((DAY(Registres!C$2:C$500)=5)*(MONTH(Registres!C$2:C$500)=$C$2)*(YEAR(Registres!C$2:C$500)=$E$2)*(TEXT(Registres!F$2:F$500,"0")=TEXT($A8,"0")))>0,"✓",""),"") | I8: =IF(6<=DAY(EOMONTH(DATE($E$2,$C$2,1),0)),IF(SUMPRODUCT((DAY(Registres!C$2:C$500)=6)*(MONTH(Registres!C$2:C$500)=$C$2)*(YEAR(Registres!C$2:C$500)=$E$2)*(TEXT(Registres!F$2:F$500,"0")=TEXT($A8,"0")))>0,"✓",""),"") | J8: =IF(7<=DAY(EOMONTH(DATE($E$2,$C$2,1),0)),IF(SUMPRODUCT((DAY(Registres!C$2:C$500)=7)*(MONTH(Registres!C$2:C$500)=$C$2)*(YEAR(Registres!C$2:C$500)=$E$2)*(TEXT(Registres!F$2:F$500,"0")=TEXT($A8,"0")))>0,"✓",""),"") | K8: =IF(8<=DAY(EOMONTH(DATE($E$2,$C$2,1),0)),IF(SUMPRODUCT((DAY(Registres!C$2:C$500)=8)*(MONTH(Registres!C$2:C$500)=$C$2)*(YEAR(Registres!C$2:C$500)=$E$2)*(TEXT(Registres!F$2:F$500,"0")=TEXT($A8,"0")))>0,"✓",""),"") | L8: =IF(9<=DAY(EOMONTH(DATE($E$2,$C$2,1),0)),IF(SUMPRODUCT((DAY(Registres!C$2:C$500)=9)*(MONTH(Registres!C$2:C$500)=$C$2)*(YEAR(Registres!C$2:C$500)=$E$2)*(TEXT(Registres!F$2:F$500,"0")=TEXT($A8,"0")))>0,"✓",""),"") | M8: =IF(10<=DAY(EOMONTH(DATE($E$2,$C$2,1),0)),IF(SUMPRODUCT((DAY(Registres!C$2:C$500)=10)*(MONTH(Registres!C$2:C$500)=$C$2)*(YEAR(Registres!C$2:C$500)=$E$2)*(TEXT(Registres!F$2:F$500,"0")=TEXT($A8,"0")))>0,"✓",""),"") | N8: =IF(11<=DAY(EOMONTH(DATE($E$2,$C$2,1),0)),IF(SUMPRODUCT((DAY(Registres!C$2:C$500)=11)*(MONTH(Registres!C$2:C$500)=$C$2)*(YEAR(Registres!C$2:C$500)=$E$2)*(TEXT(Registres!F$2:F$500,"0")=TEXT($A8,"0")))>0,"✓",""),"") | O8: =IF(12<=DAY(EOMONTH(DATE($E$2,$C$2,1),0)),IF(SUMPRODUCT((DAY(Registres!C$2:C$500)=12)*(MONTH(Registres!C$2:C$500)=$C$2)*(YEAR(Registres!C$2:C$500)=$E$2)*(TEXT(Registres!F$2:F$500,"0")=TEXT($A8,"0")))>0,"✓",""),"") | P8: =IF(13<=DAY(EOMONTH(DATE($E$2,$C$2,1),0)),IF(SUMPRODUCT((DAY(Registres!C$2:C$500)=13)*(MONTH(Registres!C$2:C$500)=$C$2)*(YEAR(Registres!C$2:C$500)=$E$2)*(TEXT(Registres!F$2:F$500,"0")=TEXT($A8,"0")))>0,"✓",""),"") | Q8: =IF(14<=DAY(EOMONTH(DATE($E$2,$C$2,1),0)),IF(SUMPRODUCT((DAY(Registres!C$2:C$500)=14)*(MONTH(Registres!C$2:C$500)=$C$2)*(YEAR(Registres!C$2:C$500)=$E$2)*(TEXT(Registres!F$2:F$500,"0")=TEXT($A8,"0")))>0,"✓",""),"") | R8: =IF(15<=DAY(EOMONTH(DATE($E$2,$C$2,1),0)),IF(SUMPRODUCT((DAY(Registres!C$2:C$500)=15)*(MONTH(Registres!C$2:C$500)=$C$2)*(YEAR(Registres!C$2:C$500)=$E$2)*(TEXT(Registres!F$2:F$500,"0")=TEXT($A8,"0")))>0,"✓",""),"") | S8: =IF(16<=DAY(EOMONTH(DATE($E$2,$C$2,1),0)),IF(SUMPRODUCT((DAY(Registres!C$2:C$500)=16)*(MONTH(Registres!C$2:C$500)=$C$2)*(YEAR(Registres!C$2:C$500)=$E$2)*(TEXT(Registres!F$2:F$500,"0")=TEXT($A8,"0")))>0,"✓",""),"") | T8: =IF(17<=DAY(EOMONTH(DATE($E$2,$C$2,1),0)),IF(SUMPRODUCT((DAY(Registres!C$2:C$500)=17)*(MONTH(Registres!C$2:C$500)=$C$2)*(YEAR(Registres!C$2:C$500)=$E$2)*(TEXT(Registres!F$2:F$500,"0")=TEXT($A8,"0")))>0,"✓",""),"") | U8: =IF(18<=DAY(EOMONTH(DATE($E$2,$C$2,1),0)),IF(SUMPRODUCT((DAY(Registres!C$2:C$500)=18)*(MONTH(Registres!C$2:C$500)=$C$2)*(YEAR(Registres!C$2:C$500)=$E$2)*(TEXT(Registres!F$2:F$500,"0")=TEXT($A8,"0")))>0,"✓",""),"") | V8: =IF(19<=DAY(EOMONTH(DATE($E$2,$C$2,1),0)),IF(SUMPRODUCT((DAY(Registres!C$2:C$500)=19)*(MONTH(Registres!C$2:C$500)=$C$2)*(YEAR(Registres!C$2:C$500)=$E$2)*(TEXT(Registres!F$2:F$500,"0")=TEXT($A8,"0")))>0,"✓",""),"") | W8: =IF(20<=DAY(EOMONTH(DATE($E$2,$C$2,1),0)),IF(SUMPRODUCT((DAY(Registres!C$2:C$500)=20)*(MONTH(Registres!C$2:C$500)=$C$2)*(YEAR(Registres!C$2:C$500)=$E$2)*(TEXT(Registres!F$2:F$500,"0")=TEXT($A8,"0")))>0,"✓",""),"") | X8: =IF(21<=DAY(EOMONTH(DATE($E$2,$C$2,1),0)),IF(SUMPRODUCT((DAY(Registres!C$2:C$500)=21)*(MONTH(Registres!C$2:C$500)=$C$2)*(YEAR(Registres!C$2:C$500)=$E$2)*(TEXT(Registres!F$2:F$500,"0")=TEXT($A8,"0")))>0,"✓",""),"") | Y8: =IF(22<=DAY(EOMONTH(DATE($E$2,$C$2,1),0)),IF(SUMPRODUCT((DAY(Registres!C$2:C$500)=22)*(MONTH(Registres!C$2:C$500)=$C$2)*(YEAR(Registres!C$2:C$500)=$E$2)*(TEXT(Registres!F$2:F$500,"0")=TEXT($A8,"0")))>0,"✓",""),"") | Z8: =IF(23<=DAY(EOMONTH(DATE($E$2,$C$2,1),0)),IF(SUMPRODUCT((DAY(Registres!C$2:C$500)=23)*(MONTH(Registres!C$2:C$500)=$C$2)*(YEAR(Registres!C$2:C$500)=$E$2)*(TEXT(Registres!F$2:F$500,"0")=TEXT($A8,"0")))>0,"✓",""),"") | AA8: =IF(24<=DAY(EOMONTH(DATE($E$2,$C$2,1),0)),IF(SUMPRODUCT((DAY(Registres!C$2:C$500)=24)*(MONTH(Registres!C$2:C$500)=$C$2)*(YEAR(Registres!C$2:C$500)=$E$2)*(TEXT(Registres!F$2:F$500,"0")=TEXT($A8,"0")))>0,"✓",""),"") | AB8: =IF(25<=DAY(EOMONTH(DATE($E$2,$C$2,1),0)),IF(SUMPRODUCT((DAY(Registres!C$2:C$500)=25)*(MONTH(Registres!C$2:C$500)=$C$2)*(YEAR(Registres!C$2:C$500)=$E$2)*(TEXT(Registres!F$2:F$500,"0")=TEXT($A8,"0")))>0,"✓",""),"") | AC8: =IF(26<=DAY(EOMONTH(DATE($E$2,$C$2,1),0)),IF(SUMPRODUCT((DAY(Registres!C$2:C$500)=26)*(MONTH(Registres!C$2:C$500)=$C$2)*(YEAR(Registres!C$2:C$500)=$E$2)*(TEXT(Registres!F$2:F$500,"0")=TEXT($A8,"0")))>0,"✓",""),"") | AD8: =IF(27<=DAY(EOMONTH(DATE($E$2,$C$2,1),0)),IF(SUMPRODUCT((DAY(Registres!C$2:C$500)=27)*(MONTH(Registres!C$2:C$500)=$C$2)*(YEAR(Registres!C$2:C$500)=$E$2)*(TEXT(Registres!F$2:F$500,"0")=TEXT($A8,"0")))>0,"✓",""),"") | AE8: =IF(28<=DAY(EOMONTH(DATE($E$2,$C$2,1),0)),IF(SUMPRODUCT((DAY(Registres!C$2:C$500)=28)*(MONTH(Registres!C$2:C$500)=$C$2)*(YEAR(Registres!C$2:C$500)=$E$2)*(TEXT(Registres!F$2:F$500,"0")=TEXT($A8,"0")))>0,"✓",""),"") | AF8: =IF(29<=DAY(EOMONTH(DATE($E$2,$C$2,1),0)),IF(SUMPRODUCT((DAY(Registres!C$2:C$500)=29)*(MONTH(Registres!C$2:C$500)=$C$2)*(YEAR(Registres!C$2:C$500)=$E$2)*(TEXT(Registres!F$2:F$500,"0")=TEXT($A8,"0")))>0,"✓",""),"") | AG8: =IF(30<=DAY(EOMONTH(DATE($E$2,$C$2,1),0)),IF(SUMPRODUCT((DAY(Registres!C$2:C$500)=30)*(MONTH(Registres!C$2:C$500)=$C$2)*(YEAR(Registres!C$2:C$500)=$E$2)*(TEXT(Registres!F$2:F$500,"0")=TEXT($A8,"0")))>0,"✓",""),"") | AH8: =IF(31<=DAY(EOMONTH(DATE($E$2,$C$2,1),0)),IF(SUMPRODUCT((DAY(Registres!C$2:C$500)=31)*(MONTH(Registres!C$2:C$500)=$C$2)*(YEAR(Registres!C$2:C$500)=$E$2)*(TEXT(Registres!F$2:F$500,"0")=TEXT($A8,"0")))>0,"✓",""),"") | AI8: =COUNTIF(D8:AH8,"✓") -> 0
A9: 5 | B9: Danna Nicole Encinas Chávez | C9: 1r ESO | D9: =IF(1<=DAY(EOMONTH(DATE($E$2,$C$2,1),0)),IF(SUMPRODUCT((DAY(Registres!C$2:C$500)=1)*(MONTH(Registres!C$2:C$500)=$C$2)*(YEAR(Registres!C$2:C$500)=$E$2)*(TEXT(Registres!F$2:F$500,"0")=TEXT($A9,"0")))>0,"✓",""),"") | E9: =IF(2<=DAY(EOMONTH(DATE($E$2,$C$2,1),0)),IF(SUMPRODUCT((DAY(Registres!C$2:C$500)=2)*(MONTH(Registres!C$2:C$500)=$C$2)*(YEAR(Registres!C$2:C$500)=$E$2)*(TEXT(Registres!F$2:F$500,"0")=TEXT($A9,"0")))>0,"✓",""),"") | F9: =IF(3<=DAY(EOMONTH(DATE($E$2,$C$2,1),0)),IF(SUMPRODUCT((DAY(Registres!C$2:C$500)=3)*(MONTH(Registres!C$2:C$500)=$C$2)*(YEAR(Registres!C$2:C$500)=$E$2)*(TEXT(Registres!F$2:F$500,"0")=TEXT($A9,"0")))>0,"✓",""),"") | G9: =IF(4<=DAY(EOMONTH(DATE($E$2,$C$2,1),0)),IF(SUMPRODUCT((DAY(Registres!C$2:C$500)=4)*(MONTH(Registres!C$2:C$500)=$C$2)*(YEAR(Registres!C$2:C$500)=$E$2)*(TEXT(Registres!F$2:F$500,"0")=TEXT($A9,"0")))>0,"✓",""),"") | H9: =IF(5<=DAY(EOMONTH(DATE($E$2,$C$2,1),0)),IF(SUMPRODUCT((DAY(Registres!C$2:C$500)=5)*(MONTH(Registres!C$2:C$500)=$C$2)*(YEAR(Registres!C$2:C$500)=$E$2)*(TEXT(Registres!F$2:F$500,"0")=TEXT($A9,"0")))>0,"✓",""),"") | I9: =IF(6<=DAY(EOMONTH(DATE($E$2,$C$2,1),0)),IF(SUMPRODUCT((DAY(Registres!C$2:C$500)=6)*(MONTH(Registres!C$2:C$500)=$C$2)*(YEAR(Registres!C$2:C$500)=$E$2)*(TEXT(Registres!F$2:F$500,"0")=TEXT($A9,"0")))>0,"✓",""),"") | J9: =IF(7<=DAY(EOMONTH(DATE($E$2,$C$2,1),0)),IF(SUMPRODUCT((DAY(Registres!C$2:C$500)=7)*(MONTH(Registres!C$2:C$500)=$C$2)*(YEAR(Registres!C$2:C$500)=$E$2)*(TEXT(Registres!F$2:F$500,"0")=TEXT($A9,"0")))>0,"✓",""),"") | K9: =IF(8<=DAY(EOMONTH(DATE($E$2,$C$2,1),0)),IF(SUMPRODUCT((DAY(Registres!C$2:C$500)=8)*(MONTH(Registres!C$2:C$500)=$C$2)*(YEAR(Registres!C$2:C$500)=$E$2)*(TEXT(Registres!F$2:F$500,"0")=TEXT($A9,"0")))>0,"✓",""),"") | L9: =IF(9<=DAY(EOMONTH(DATE($E$2,$C$2,1),0)),IF(SUMPRODUCT((DAY(Registres!C$2:C$500)=9)*(MONTH(Registres!C$2:C$500)=$C$2)*(YEAR(Registres!C$2:C$500)=$E$2)*(TEXT(Registres!F$2:F$500,"0")=TEXT($A9,"0")))>0,"✓",""),"") | M9: =IF(10<=DAY(EOMONTH(DATE($E$2,$C$2,1),0)),IF(SUMPRODUCT((DAY(Registres!C$2:C$500)=10)*(MONTH(Registres!C$2:C$500)=$C$2)*(YEAR(Registres!C$2:C$500)=$E$2)*(TEXT(Registres!F$2:F$500,"0")=TEXT($A9,"0")))>0,"✓",""),"") | N9: =IF(11<=DAY(EOMONTH(DATE($E$2,$C$2,1),0)),IF(SUMPRODUCT((DAY(Registres!C$2:C$500)=11)*(MONTH(Registres!C$2:C$500)=$C$2)*(YEAR(Registres!C$2:C$500)=$E$2)*(TEXT(Registres!F$2:F$500,"0")=TEXT($A9,"0")))>0,"✓",""),"") | O9: =IF(12<=DAY(EOMONTH(DATE($E$2,$C$2,1),0)),IF(SUMPRODUCT((DAY(Registres!C$2:C$500)=12)*(MONTH(Registres!C$2:C$500)=$C$2)*(YEAR(Registres!C$2:C$500)=$E$2)*(TEXT(Registres!F$2:F$500,"0")=TEXT($A9,"0")))>0,"✓",""),"") | P9: =IF(13<=DAY(EOMONTH(DATE($E$2,$C$2,1),0)),IF(SUMPRODUCT((DAY(Registres!C$2:C$500)=13)*(MONTH(Registres!C$2:C$500)=$C$2)*(YEAR(Registres!C$2:C$500)=$E$2)*(TEXT(Registres!F$2:F$500,"0")=TEXT($A9,"0")))>0,"✓",""),"") | Q9: =IF(14<=DAY(EOMONTH(DATE($E$2,$C$2,1),0)),IF(SUMPRODUCT((DAY(Registres!C$2:C$500)=14)*(MONTH(Registres!C$2:C$500)=$C$2)*(YEAR(Registres!C$2:C$500)=$E$2)*(TEXT(Registres!F$2:F$500,"0")=TEXT($A9,"0")))>0,"✓",""),"") | R9: =IF(15<=DAY(EOMONTH(DATE($E$2,$C$2,1),0)),IF(SUMPRODUCT((DAY(Registres!C$2:C$500)=15)*(MONTH(Registres!C$2:C$500)=$C$2)*(YEAR(Registres!C$2:C$500)=$E$2)*(TEXT(Registres!F$2:F$500,"0")=TEXT($A9,"0")))>0,"✓",""),"") | S9: =IF(16<=DAY(EOMONTH(DATE($E$2,$C$2,1),0)),IF(SUMPRODUCT((DAY(Registres!C$2:C$500)=16)*(MONTH(Registres!C$2:C$500)=$C$2)*(YEAR(Registres!C$2:C$500)=$E$2)*(TEXT(Registres!F$2:F$500,"0")=TEXT($A9,"0")))>0,"✓",""),"") | T9: =IF(17<=DAY(EOMONTH(DATE($E$2,$C$2,1),0)),IF(SUMPRODUCT((DAY(Registres!C$2:C$500)=17)*(MONTH(Registres!C$2:C$500)=$C$2)*(YEAR(Registres!C$2:C$500)=$E$2)*(TEXT(Registres!F$2:F$500,"0")=TEXT($A9,"0")))>0,"✓",""),"") | U9: =IF(18<=DAY(EOMONTH(DATE($E$2,$C$2,1),0)),IF(SUMPRODUCT((DAY(Registres!C$2:C$500)=18)*(MONTH(Registres!C$2:C$500)=$C$2)*(YEAR(Registres!C$2:C$500)=$E$2)*(TEXT(Registres!F$2:F$500,"0")=TEXT($A9,"0")))>0,"✓",""),"") | V9: =IF(19<=DAY(EOMONTH(DATE($E$2,$C$2,1),0)),IF(SUMPRODUCT((DAY(Registres!C$2:C$500)=19)*(MONTH(Registres!C$2:C$500)=$C$2)*(YEAR(Registres!C$2:C$500)=$E$2)*(TEXT(Registres!F$2:F$500,"0")=TEXT($A9,"0")))>0,"✓",""),"") | W9: =IF(20<=DAY(EOMONTH(DATE($E$2,$C$2,1),0)),IF(SUMPRODUCT((DAY(Registres!C$2:C$500)=20)*(MONTH(Registres!C$2:C$500)=$C$2)*(YEAR(Registres!C$2:C$500)=$E$2)*(TEXT(Registres!F$2:F$500,"0")=TEXT($A9,"0")))>0,"✓",""),"") | X9: =IF(21<=DAY(EOMONTH(DATE($E$2,$C$2,1),0)),IF(SUMPRODUCT((DAY(Registres!C$2:C$500)=21)*(MONTH(Registres!C$2:C$500)=$C$2)*(YEAR(Registres!C$2:C$500)=$E$2)*(TEXT(Registres!F$2:F$500,"0")=TEXT($A9,"0")))>0,"✓",""),"") | Y9: =IF(22<=DAY(EOMONTH(DATE($E$2,$C$2,1),0)),IF(SUMPRODUCT((DAY(Registres!C$2:C$500)=22)*(MONTH(Registres!C$2:C$500)=$C$2)*(YEAR(Registres!C$2:C$500)=$E$2)*(TEXT(Registres!F$2:F$500,"0")=TEXT($A9,"0")))>0,"✓",""),"") | Z9: =IF(23<=DAY(EOMONTH(DATE($E$2,$C$2,1),0)),IF(SUMPRODUCT((DAY(Registres!C$2:C$500)=23)*(MONTH(Registres!C$2:C$500)=$C$2)*(YEAR(Registres!C$2:C$500)=$E$2)*(TEXT(Registres!F$2:F$500,"0")=TEXT($A9,"0")))>0,"✓",""),"") | AA9: =IF(24<=DAY(EOMONTH(DATE($E$2,$C$2,1),0)),IF(SUMPRODUCT((DAY(Registres!C$2:C$500)=24)*(MONTH(Registres!C$2:C$500)=$C$2)*(YEAR(Registres!C$2:C$500)=$E$2)*(TEXT(Registres!F$2:F$500,"0")=TEXT($A9,"0")))>0,"✓",""),"") | AB9: =IF(25<=DAY(EOMONTH(DATE($E$2,$C$2,1),0)),IF(SUMPRODUCT((DAY(Registres!C$2:C$500)=25)*(MONTH(Registres!C$2:C$500)=$C$2)*(YEAR(Registres!C$2:C$500)=$E$2)*(TEXT(Registres!F$2:F$500,"0")=TEXT($A9,"0")))>0,"✓",""),"") | AC9: =IF(26<=DAY(EOMONTH(DATE($E$2,$C$2,1),0)),IF(SUMPRODUCT((DAY(Registres!C$2:C$500)=26)*(MONTH(Registres!C$2:C$500)=$C$2)*(YEAR(Registres!C$2:C$500)=$E$2)*(TEXT(Registres!F$2:F$500,"0")=TEXT($A9,"0")))>0,"✓",""),"") | AD9: =IF(27<=DAY(EOMONTH(DATE($E$2,$C$2,1),0)),IF(SUMPRODUCT((DAY(Registres!C$2:C$500)=27)*(MONTH(Registres!C$2:C$500)=$C$2)*(YEAR(Registres!C$2:C$500)=$E$2)*(TEXT(Registres!F$2:F$500,"0")=TEXT($A9,"0")))>0,"✓",""),"") | AE9: =IF(28<=DAY(EOMONTH(DATE($E$2,$C$2,1),0)),IF(SUMPRODUCT((DAY(Registres!C$2:C$500)=28)*(MONTH(Registres!C$2:C$500)=$C$2)*(YEAR(Registres!C$2:C$500)=$E$2)*(TEXT(Registres!F$2:F$500,"0")=TEXT($A9,"0")))>0,"✓",""),"") | AF9: =IF(29<=DAY(EOMONTH(DATE($E$2,$C$2,1),0)),IF(SUMPRODUCT((DAY(Registres!C$2:C$500)=29)*(MONTH(Registres!C$2:C$500)=$C$2)*(YEAR(Registres!C$2:C$500)=$E$2)*(TEXT(Registres!F$2:F$500,"0")=TEXT($A9,"0")))>0,"✓",""),"") | AG9: =IF(30<=DAY(EOMONTH(DATE($E$2,$C$2,1),0)),IF(SUMPRODUCT((DAY(Registres!C$2:C$500)=30)*(MONTH(Registres!C$2:C$500)=$C$2)*(YEAR(Registres!C$2:C$500)=$E$2)*(TEXT(Registres!F$2:F$500,"0")=TEXT($A9,"0")))>0,"✓",""),"") | AH9: =IF(31<=DAY(EOMONTH(DATE($E$2,$C$2,1),0)),IF(SUMPRODUCT((DAY(Registres!C$2:C$500)=31)*(MONTH(Registres!C$2:C$500)=$C$2)*(YEAR(Registres!C$2:C$500)=$E$2)*(TEXT(Registres!F$2:F$500,"0")=TEXT($A9,"0")))>0,"✓",""),"") | AI9: =COUNTIF(D9:AH9,"✓") -> 0
A10: 6 | B10: Ainoa Sofia Falcon Garcia | C10: 1r ESO | D10: =IF(1<=DAY(EOMONTH(DATE($E$2,$C$2,1),0)),IF(SUMPRODUCT((DAY(Registres!C$2:C$500)=1)*(MONTH(Registres!C$2:C$500)=$C$2)*(YEAR(Registres!C$2:C$500)=$E$2)*(TEXT(Registres!F$2:F$500,"0")=TEXT($A10,"0")))>0,"✓",""),"") | E10: =IF(2<=DAY(EOMONTH(DATE($E$2,$C$2,1),0)),IF(SUMPRODUCT((DAY(Registres!C$2:C$500)=2)*(MONTH(Registres!C$2:C$500)=$C$2)*(YEAR(Registres!C$2:C$500)=$E$2)*(TEXT(Registres!F$2:F$500,"0")=TEXT($A10,"0")))>0,"✓",""),"") | F10: =IF(3<=DAY(EOMONTH(DATE($E$2,$C$2,1),0)),IF(SUMPRODUCT((DAY(Registres!C$2:C$500)=3)*(MONTH(Registres!C$2:C$500)=$C$2)*(YEAR(Registres!C$2:C$500)=$E$2)*(TEXT(Registres!F$2:F$500,"0")=TEXT($A10,"0")))>0,"✓",""),"") | G10: =IF(4<=DAY(EOMONTH(DATE($E$2,$C$2,1),0)),IF(SUMPRODUCT((DAY(Registres!C$2:C$500)=4)*(MONTH(Registres!C$2:C$500)=$C$2)*(YEAR(Registres!C$2:C$500)=$E$2)*(TEXT(Registres!F$2:F$500,"0")=TEXT($A10,"0")))>0,"✓",""),"") | H10: =IF(5<=DAY(EOMONTH(DATE($E$2,$C$2,1),0)),IF(SUMPRODUCT((DAY(Registres!C$2:C$500)=5)*(MONTH(Registres!C$2:C$500)=$C$2)*(YEAR(Registres!C$2:C$500)=$E$2)*(TEXT(Registres!F$2:F$500,"0")=TEXT($A10,"0")))>0,"✓",""),"") | I10: =IF(6<=DAY(EOMONTH(DATE($E$2,$C$2,1),0)),IF(SUMPRODUCT((DAY(Registres!C$2:C$500)=6)*(MONTH(Registres!C$2:C$500)=$C$2)*(YEAR(Registres!C$2:C$500)=$E$2)*(TEXT(Registres!F$2:F$500,"0")=TEXT($A10,"0")))>0,"✓",""),"") | J10: =IF(7<=DAY(EOMONTH(DATE($E$2,$C$2,1),0)),IF(SUMPRODUCT((DAY(Registres!C$2:C$500)=7)*(MONTH(Registres!C$2:C$500)=$C$2)*(YEAR(Registres!C$2:C$500)=$E$2)*(TEXT(Registres!F$2:F$500,"0")=TEXT($A10,"0")))>0,"✓",""),"") | K10: =IF(8<=DAY(EOMONTH(DATE($E$2,$C$2,1),0)),IF(SUMPRODUCT((DAY(Registres!C$2:C$500)=8)*(MONTH(Registres!C$2:C$500)=$C$2)*(YEAR(Registres!C$2:C$500)=$E$2)*(TEXT(Registres!F$2:F$500,"0")=TEXT($A10,"0")))>0,"✓",""),"") | L10: =IF(9<=DAY(EOMONTH(DATE($E$2,$C$2,1),0)),IF(SUMPRODUCT((DAY(Registres!C$2:C$500)=9)*(MONTH(Registres!C$2:C$500)=$C$2)*(YEAR(Registres!C$2:C$500)=$E$2)*(TEXT(Registres!F$2:F$500,"0")=TEXT($A10,"0")))>0,"✓",""),"") | M10: =IF(10<=DAY(EOMONTH(DATE($E$2,$C$2,1),0)),IF(SUMPRODUCT((DAY(Registres!C$2:C$500)=10)*(MONTH(Registres!C$2:C$500)=$C$2)*(YEAR(Registres!C$2:C$500)=$E$2)*(TEXT(Registres!F$2:F$500,"0")=TEXT($A10,"0")))>0,"✓",""),"") | N10: =IF(11<=DAY(EOMONTH(DATE($E$2,$C$2,1),0)),IF(SUMPRODUCT((DAY(Registres!C$2:C$500)=11)*(MONTH(Registres!C$2:C$500)=$C$2)*(YEAR(Registres!C$2:C$500)=$E$2)*(TEXT(Registres!F$2:F$500,"0")=TEXT($A10,"0")))>0,"✓",""),"") | O10: =IF(12<=DAY(EOMONTH(DATE($E$2,$C$2,1),0)),IF(SUMPRODUCT((DAY(Registres!C$2:C$500)=12)*(MONTH(Registres!C$2:C$500)=$C$2)*(YEAR(Registres!C$2:C$500)=$E$2)*(TEXT(Registres!F$2:F$500,"0")=TEXT($A10,"0")))>0,"✓",""),"") | P10: =IF(13<=DAY(EOMONTH(DATE($E$2,$C$2,1),0)),IF(SUMPRODUCT((DAY(Registres!C$2:C$500)=13)*(MONTH(Registres!C$2:C$500)=$C$2)*(YEAR(Registres!C$2:C$500)=$E$2)*(TEXT(Registres!F$2:F$500,"0")=TEXT($A10,"0")))>0,"✓",""),"") | Q10: =IF(14<=DAY(EOMONTH(DATE($E$2,$C$2,1),0)),IF(SUMPRODUCT((DAY(Registres!C$2:C$500)=14)*(MONTH(Registres!C$2:C$500)=$C$2)*(YEAR(Registres!C$2:C$500)=$E$2)*(TEXT(Registres!F$2:F$500,"0")=TEXT($A10,"0")))>0,"✓",""),"") | R10: =IF(15<=DAY(EOMONTH(DATE($E$2,$C$2,1),0)),IF(SUMPRODUCT((DAY(Registres!C$2:C$500)=15)*(MONTH(Registres!C$2:C$500)=$C$2)*(YEAR(Registres!C$2:C$500)=$E$2)*(TEXT(Registres!F$2:F$500,"0")=TEXT($A10,"0")))>0,"✓",""),"") | S10: =IF(16<=DAY(EOMONTH(DATE($E$2,$C$2,1),0)),IF(SUMPRODUCT((DAY(Registres!C$2:C$500)=16)*(MONTH(Registres!C$2:C$500)=$C$2)*(YEAR(Registres!C$2:C$500)=$E$2)*(TEXT(Registres!F$2:F$500,"0")=TEXT($A10,"0")))>0,"✓",""),"") | T10: =IF(17<=DAY(EOMONTH(DATE($E$2,$C$2,1),0)),IF(SUMPRODUCT((DAY(Registres!C$2:C$500)=17)*(MONTH(Registres!C$2:C$500)=$C$2)*(YEAR(Registres!C$2:C$500)=$E$2)*(TEXT(Registres!F$2:F$500,"0")=TEXT($A10,"0")))>0,"✓",""),"") | U10: =IF(18<=DAY(EOMONTH(DATE($E$2,$C$2,1),0)),IF(SUMPRODUCT((DAY(Registres!C$2:C$500)=18)*(MONTH(Registres!C$2:C$500)=$C$2)*(YEAR(Registres!C$2:C$500)=$E$2)*(TEXT(Registres!F$2:F$500,"0")=TEXT($A10,"0")))>0,"✓",""),"") | V10: =IF(19<=DAY(EOMONTH(DATE($E$2,$C$2,1),0)),IF(SUMPRODUCT((DAY(Registres!C$2:C$500)=19)*(MONTH(Registres!C$2:C$500)=$C$2)*(YEAR(Registres!C$2:C$500)=$E$2)*(TEXT(Registres!F$2:F$500,"0")=TEXT($A10,"0")))>0,"✓",""),"") | W10: =IF(20<=DAY(EOMONTH(DATE($E$2,$C$2,1),0)),IF(SUMPRODUCT((DAY(Registres!C$2:C$500)=20)*(MONTH(Registres!C$2:C$500)=$C$2)*(YEAR(Registres!C$2:C$500)=$E$2)*(TEXT(Registres!F$2:F$500,"0")=TEXT($A10,"0")))>0,"✓",""),"") | X10: =IF(21<=DAY(EOMONTH(DATE($E$2,$C$2,1),0)),IF(SUMPRODUCT((DAY(Registres!C$2:C$500)=21)*(MONTH(Registres!C$2:C$500)=$C$2)*(YEAR(Registres!C$2:C$500)=$E$2)*(TEXT(Registres!F$2:F$500,"0")=TEXT($A10,"0")))>0,"✓",""),"") | Y10: =IF(22<=DAY(EOMONTH(DATE($E$2,$C$2,1),0)),IF(SUMPRODUCT((DAY(Registres!C$2:C$500)=22)*(MONTH(Registres!C$2:C$500)=$C$2)*(YEAR(Registres!C$2:C$500)=$E$2)*(TEXT(Registres!F$2:F$500,"0")=TEXT($A10,"0")))>0,"✓",""),"") | Z10: =IF(23<=DAY(EOMONTH(DATE($E$2,$C$2,1),0)),IF(SUMPRODUCT((DAY(Registres!C$2:C$500)=23)*(MONTH(Registres!C$2:C$500)=$C$2)*(YEAR(Registres!C$2:C$500)=$E$2)*(TEXT(Registres!F$2:F$500,"0")=TEXT($A10,"0")))>0,"✓",""),"") | AA10: =IF(24<=DAY(EOMONTH(DATE($E$2,$C$2,1),0)),IF(SUMPRODUCT((DAY(Registres!C$2:C$500)=24)*(MONTH(Registres!C$2:C$500)=$C$2)*(YEAR(Registres!C$2:C$500)=$E$2)*(TEXT(Registres!F$2:F$500,"0")=TEXT($A10,"0")))>0,"✓",""),"") | AB10: =IF(25<=DAY(EOMONTH(DATE($E$2,$C$2,1),0)),IF(SUMPRODUCT((DAY(Registres!C$2:C$500)=25)*(MONTH(Registres!C$2:C$500)=$C$2)*(YEAR(Registres!C$2:C$500)=$E$2)*(TEXT(Registres!F$2:F$500,"0")=TEXT($A10,"0")))>0,"✓",""),"") | AC10: =IF(26<=DAY(EOMONTH(DATE($E$2,$C$2,1),0)),IF(SUMPRODUCT((DAY(Registres!C$2:C$500)=26)*(MONTH(Registres!C$2:C$500)=$C$2)*(YEAR(Registres!C$2:C$500)=$E$2)*(TEXT(Registres!F$2:F$500,"0")=TEXT($A10,"0")))>0,"✓",""),"") | AD10: =IF(27<=DAY(EOMONTH(DATE($E$2,$C$2,1),0)),IF(SUMPRODUCT((DAY(Registres!C$2:C$500)=27)*(MONTH(Registres!C$2:C$500)=$C$2)*(YEAR(Registres!C$2:C$500)=$E$2)*(TEXT(Registres!F$2:F$500,"0")=TEXT($A10,"0")))>0,"✓",""),"") | AE10: =IF(28<=DAY(EOMONTH(DATE($E$2,$C$2,1),0)),IF(SUMPRODUCT((DAY(Registres!C$2:C$500)=28)*(MONTH(Registres!C$2:C$500)=$C$2)*(YEAR(Registres!C$2:C$500)=$E$2)*(TEXT(Registres!F$2:F$500,"0")=TEXT($A10,"0")))>0,"✓",""),"") | AF10: =IF(29<=DAY(EOMONTH(DATE($E$2,$C$2,1),0)),IF(SUMPRODUCT((DAY(Registres!C$2:C$500)=29)*(MONTH(Registres!C$2:C$500)=$C$2)*(YEAR(Registres!C$2:C$500)=$E$2)*(TEXT(Registres!F$2:F$500,"0")=TEXT($A10,"0")))>0,"✓",""),"") | AG10: =IF(30<=DAY(EOMONTH(DATE($E$2,$C$2,1),0)),IF(SUMPRODUCT((DAY(Registres!C$2:C$500)=30)*(MONTH(Registres!C$2:C$500)=$C$2)*(YEAR(Registres!C$2:C$500)=$E$2)*(TEXT(Registres!F$2:F$500,"0")=TEXT($A10,"0")))>0,"✓",""),"") | AH10: =IF(31<=DAY(EOMONTH(DATE($E$2,$C$2,1),0)),IF(SUMPRODUCT((DAY(Registres!C$2:C$500)=31)*(MONTH(Registres!C$2:C$500)=$C$2)*(YEAR(Registres!C$2:C$500)=$E$2)*(TEXT(Registres!F$2:F$500,"0")=TEXT($A10,"0")))>0,"✓",""),"") | AI10: =COUNTIF(D10:AH10,"✓") -> 0
A11: 7 | B11: Anderson Mauricio Gutama Londoño | C11: 1r ESO | D11: =IF(1<=DAY(EOMONTH(DATE($E$2,$C$2,1),0)),IF(SUMPRODUCT((DAY(Registres!C$2:C$500)=1)*(MONTH(Registres!C$2:C$500)=$C$2)*(YEAR(Registres!C$2:C$500)=$E$2)*(TEXT(Registres!F$2:F$500,"0")=TEXT($A11,"0")))>0,"✓",""),"") | E11: =IF(2<=DAY(EOMONTH(DATE($E$2,$C$2,1),0)),IF(SUMPRODUCT((DAY(Registres!C$2:C$500)=2)*(MONTH(Registres!C$2:C$500)=$C$2)*(YEAR(Registres!C$2:C$500)=$E$2)*(TEXT(Registres!F$2:F$500,"0")=TEXT($A11,"0")))>0,"✓",""),"") | F11: =IF(3<=DAY(EOMONTH(DATE($E$2,$C$2,1),0)),IF(SUMPRODUCT((DAY(Registres!C$2:C$500)=3)*(MONTH(Registres!C$2:C$500)=$C$2)*(YEAR(Registres!C$2:C$500)=$E$2)*(TEXT(Registres!F$2:F$500,"0")=TEXT($A11,"0")))>0,"✓",""),"") | G11: =IF(4<=DAY(EOMONTH(DATE($E$2,$C$2,1),0)),IF(SUMPRODUCT((DAY(Registres!C$2:C$500)=4)*(MONTH(Registres!C$2:C$500)=$C$2)*(YEAR(Registres!C$2:C$500)=$E$2)*(TEXT(Registres!F$2:F$500,"0")=TEXT($A11,"0")))>0,"✓",""),"") | H11: =IF(5<=DAY(EOMONTH(DATE($E$2,$C$2,1),0)),IF(SUMPRODUCT((DAY(Registres!C$2:C$500)=5)*(MONTH(Registres!C$2:C$500)=$C$2)*(YEAR(Registres!C$2:C$500)=$E$2)*(TEXT(Registres!F$2:F$500,"0")=TEXT($A11,"0")))>0,"✓",""),"") | I11: =IF(6<=DAY(EOMONTH(DATE($E$2,$C$2,1),0)),IF(SUMPRODUCT((DAY(Registres!C$2:C$500)=6)*(MONTH(Registres!C$2:C$500)=$C$2)*(YEAR(Registres!C$2:C$500)=$E$2)*(TEXT(Registres!F$2:F$500,"0")=TEXT($A11,"0")))>0,"✓",""),"") | J11: =IF(7<=DAY(EOMONTH(DATE($E$2,$C$2,1),0)),IF(SUMPRODUCT((DAY(Registres!C$2:C$500)=7)*(MONTH(Registres!C$2:C$500)=$C$2)*(YEAR(Registres!C$2:C$500)=$E$2)*(TEXT(Registres!F$2:F$500,"0")=TEXT($A11,"0")))>0,"✓",""),"") | K11: =IF(8<=DAY(EOMONTH(DATE($E$2,$C$2,1),0)),IF(SUMPRODUCT((DAY(Registres!C$2:C$500)=8)*(MONTH(Registres!C$2:C$500)=$C$2)*(YEAR(Registres!C$2:C$500)=$E$2)*(TEXT(Registres!F$2:F$500,"0")=TEXT($A11,"0")))>0,"✓",""),"") | L11: =IF(9<=DAY(EOMONTH(DATE($E$2,$C$2,1),0)),IF(SUMPRODUCT((DAY(Registres!C$2:C$500)=9)*(MONTH(Registres!C$2:C$500)=$C$2)*(YEAR(Registres!C$2:C$500)=$E$2)*(TEXT(Registres!F$2:F$500,"0")=TEXT($A11,"0")))>0,"✓",""),"") | M11: =IF(10<=DAY(EOMONTH(DATE($E$2,$C$2,1),0)),IF(SUMPRODUCT((DAY(Registres!C$2:C$500)=10)*(MONTH(Registres!C$2:C$500)=$C$2)*(YEAR(Registres!C$2:C$500)=$E$2)*(TEXT(Registres!F$2:F$500,"0")=TEXT($A11,"0")))>0,"✓",""),"") | N11: =IF(11<=DAY(EOMONTH(DATE($E$2,$C$2,1),0)),IF(SUMPRODUCT((DAY(Registres!C$2:C$500)=11)*(MONTH(Registres!C$2:C$500)=$C$2)*(YEAR(Registres!C$2:C$500)=$E$2)*(TEXT(Registres!F$2:F$500,"0")=TEXT($A11,"0")))>0,"✓",""),"") | O11: =IF(12<=DAY(EOMONTH(DATE($E$2,$C$2,1),0)),IF(SUMPRODUCT((DAY(Registres!C$2:C$500)=12)*(MONTH(Registres!C$2:C$500)=$C$2)*(YEAR(Registres!C$2:C$500)=$E$2)*(TEXT(Registres!F$2:F$500,"0")=TEXT($A11,"0")))>0,"✓",""),"") | P11: =IF(13<=DAY(EOMONTH(DATE($E$2,$C$2,1),0)),IF(SUMPRODUCT((DAY(Registres!C$2:C$500)=13)*(MONTH(Registres!C$2:C$500)=$C$2)*(YEAR(Registres!C$2:C$500)=$E$2)*(TEXT(Registres!F$2:F$500,"0")=TEXT($A11,"0")))>0,"✓",""),"") | Q11: =IF(14<=DAY(EOMONTH(DATE($E$2,$C$2,1),0)),IF(SUMPRODUCT((DAY(Registres!C$2:C$500)=14)*(MONTH(Registres!C$2:C$500)=$C$2)*(YEAR(Registres!C$2:C$500)=$E$2)*(TEXT(Registres!F$2:F$500,"0")=TEXT($A11,"0")))>0,"✓",""),"") | R11: =IF(15<=DAY(EOMONTH(DATE($E$2,$C$2,1),0)),IF(SUMPRODUCT((DAY(Registres!C$2:C$500)=15)*(MONTH(Registres!C$2:C$500)=$C$2)*(YEAR(Registres!C$2:C$500)=$E$2)*(TEXT(Registres!F$2:F$500,"0")=TEXT($A11,"0")))>0,"✓",""),"") | S11: =IF(16<=DAY(EOMONTH(DATE($E$2,$C$2,1),0)),IF(SUMPRODUCT((DAY(Registres!C$2:C$500)=16)*(MONTH(Registres!C$2:C$500)=$C$2)*(YEAR(Registres!C$2:C$500)=$E$2)*(TEXT(Registres!F$2:F$500,"0")=TEXT($A11,"0")))>0,"✓",""),"") | T11: =IF(17<=DAY(EOMONTH(DATE($E$2,$C$2,1),0)),IF(SUMPRODUCT((DAY(Registres!C$2:C$500)=17)*(MONTH(Registres!C$2:C$500)=$C$2)*(YEAR(Registres!C$2:C$500)=$E$2)*(TEXT(Registres!F$2:F$500,"0")=TEXT($A11,"0")))>0,"✓",""),"") | U11: =IF(18<=DAY(EOMONTH(DATE($E$2,$C$2,1),0)),IF(SUMPRODUCT((DAY(Registres!C$2:C$500)=18)*(MONTH(Registres!C$2:C$500)=$C$2)*(YEAR(Registres!C$2:C$500)=$E$2)*(TEXT(Registres!F$2:F$500,"0")=TEXT($A11,"0")))>0,"✓",""),"") | V11: =IF(19<=DAY(EOMONTH(DATE($E$2,$C$2,1),0)),IF(SUMPRODUCT((DAY(Registres!C$2:C$500)=19)*(MONTH(Registres!C$2:C$500)=$C$2)*(YEAR(Registres!C$2:C$500)=$E$2)*(TEXT(Registres!F$2:F$500,"0")=TEXT($A11,"0")))>0,"✓",""),"") | W11: =IF(20<=DAY(EOMONTH(DATE($E$2,$C$2,1),0)),IF(SUMPRODUCT((DAY(Registres!C$2:C$500)=20)*(MONTH(Registres!C$2:C$500)=$C$2)*(YEAR(Registres!C$2:C$500)=$E$2)*(TEXT(Registres!F$2:F$500,"0")=TEXT($A11,"0")))>0,"✓",""),"") | X11: =IF(21<=DAY(EOMONTH(DATE($E$2,$C$2,1),0)),IF(SUMPRODUCT((DAY(Registres!C$2:C$500)=21)*(MONTH(Registres!C$2:C$500)=$C$2)*(YEAR(Registres!C$2:C$500)=$E$2)*(TEXT(Registres!F$2:F$500,"0")=TEXT($A11,"0")))>0,"✓",""),"") | Y11: =IF(22<=DAY(EOMONTH(DATE($E$2,$C$2,1),0)),IF(SUMPRODUCT((DAY(Registres!C$2:C$500)=22)*(MONTH(Registres!C$2:C$500)=$C$2)*(YEAR(Registres!C$2:C$500)=$E$2)*(TEXT(Registres!F$2:F$500,"0")=TEXT($A11,"0")))>0,"✓",""),"") | Z11: =IF(23<=DAY(EOMONTH(DATE($E$2,$C$2,1),0)),IF(SUMPRODUCT((DAY(Registres!C$2:C$500)=23)*(MONTH(Registres!C$2:C$500)=$C$2)*(YEAR(Registres!C$2:C$500)=$E$2)*(TEXT(Registres!F$2:F$500,"0")=TEXT($A11,"0")))>0,"✓",""),"") | AA11: =IF(24<=DAY(EOMONTH(DATE($E$2,$C$2,1),0)),IF(SUMPRODUCT((DAY(Registres!C$2:C$500)=24)*(MONTH(Registres!C$2:C$500)=$C$2)*(YEAR(Registres!C$2:C$500)=$E$2)*(TEXT(Registres!F$2:F$500,"0")=TEXT($A11,"0")))>0,"✓",""),"") | AB11: =IF(25<=DAY(EOMONTH(DATE($E$2,$C$2,1),0)),IF(SUMPRODUCT((DAY(Registres!C$2:C$500)=25)*(MONTH(Registres!C$2:C$500)=$C$2)*(YEAR(Registres!C$2:C$500)=$E$2)*(TEXT(Registres!F$2:F$500,"0")=TEXT($A11,"0")))>0,"✓",""),"") | AC11: =IF(26<=DAY(EOMONTH(DATE($E$2,$C$2,1),0)),IF(SUMPRODUCT((DAY(Registres!C$2:C$500)=26)*(MONTH(Registres!C$2:C$500)=$C$2)*(YEAR(Registres!C$2:C$500)=$E$2)*(TEXT(Registres!F$2:F$500,"0")=TEXT($A11,"0")))>0,"✓",""),"") | AD11: =IF(27<=DAY(EOMONTH(DATE($E$2,$C$2,1),0)),IF(SUMPRODUCT((DAY(Registres!C$2:C$500)=27)*(MONTH(Registres!C$2:C$500)=$C$2)*(YEAR(Registres!C$2:C$500)=$E$2)*(TEXT(Registres!F$2:F$500,"0")=TEXT($A11,"0")))>0,"✓",""),"") | AE11: =IF(28<=DAY(EOMONTH(DATE($E$2,$C$2,1),0)),IF(SUMPRODUCT((DAY(Registres!C$2:C$500)=28)*(MONTH(Registres!C$2:C$500)=$C$2)*(YEAR(Registres!C$2:C$500)=$E$2)*(TEXT(Registres!F$2:F$500,"0")=TEXT($A11,"0")))>0,"✓",""),"") | AF11: =IF(29<=DAY(EOMONTH(DATE($E$2,$C$2,1),0)),IF(SUMPRODUCT((DAY(Registres!C$2:C$500)=29)*(MONTH(Registres!C$2:C$500)=$C$2)*(YEAR(Registres!C$2:C$500)=$E$2)*(TEXT(Registres!F$2:F$500,"0")=TEXT($A11,"0")))>0,"✓",""),"") | AG11: =IF(30<=DAY(EOMONTH(DATE($E$2,$C$2,1),0)),IF(SUMPRODUCT((DAY(Registres!C$2:C$500)=30)*(MONTH(Registres!C$2:C$500)=$C$2)*(YEAR(Registres!C$2:C$500)=$E$2)*(TEXT(Registres!F$2:F$500,"0")=TEXT($A11,"0")))>0,"✓",""),"") | AH11: =IF(31<=DAY(EOMONTH(DATE($E$2,$C$2,1),0)),IF(SUMPRODUCT((DAY(Registres!C$2:C$500)=31)*(MONTH(Registres!C$2:C$500)=$C$2)*(YEAR(Registres!C$2:C$500)=$E$2)*(TEXT(Registres!F$2:F$500,"0")=TEXT($A11,"0")))>0,"✓",""),"") | AI11: =COUNTIF(D11:AH11,"✓") -> 0
A12: 8 | B12: Keira Daniela Loor Sifuentes | C12: 1r ESO | D12: =IF(1<=DAY(EOMONTH(DATE($E$2,$C$2,1),0)),IF(SUMPRODUCT((DAY(Registres!C$2:C$500)=1)*(MONTH(Registres!C$2:C$500)=$C$2)*(YEAR(Registres!C$2:C$500)=$E$2)*(TEXT(Registres!F$2:F$500,"0")=TEXT($A12,"0")))>0,"✓",""),"") | E12: =IF(2<=DAY(EOMONTH(DATE($E$2,$C$2,1),0)),IF(SUMPRODUCT((DAY(Registres!C$2:C$500)=2)*(MONTH(Registres!C$2:C$500)=$C$2)*(YEAR(Registres!C$2:C$500)=$E$2)*(TEXT(Registres!F$2:F$500,"0")=TEXT($A12,"0")))>0,"✓",""),"") | F12: =IF(3<=DAY(EOMONTH(DATE($E$2,$C$2,1),0)),IF(SUMPRODUCT((DAY(Registres!C$2:C$500)=3)*(MONTH(Registres!C$2:C$500)=$C$2)*(YEAR(Registres!C$2:C$500)=$E$2)*(TEXT(Registres!F$2:F$500,"0")=TEXT($A12,"0")))>0,"✓",""),"") | G12: =IF(4<=DAY(EOMONTH(DATE($E$2,$C$2,1),0)),IF(SUMPRODUCT((DAY(Registres!C$2:C$500)=4)*(MONTH(Registres!C$2:C$500)=$C$2)*(YEAR(Registres!C$2:C$500)=$E$2)*(TEXT(Registres!F$2:F$500,"0")=TEXT($A12,"0")))>0,"✓",""),"") | H12: =IF(5<=DAY(EOMONTH(DATE($E$2,$C$2,1),0)),IF(SUMPRODUCT((DAY(Registres!C$2:C$500)=5)*(MONTH(Registres!C$2:C$500)=$C$2)*(YEAR(Registres!C$2:C$500)=$E$2)*(TEXT(Registres!F$2:F$500,"0")=TEXT($A12,"0")))>0,"✓",""),"") | I12: =IF(6<=DAY(EOMONTH(DATE($E$2,$C$2,1),0)),IF(SUMPRODUCT((DAY(Registres!C$2:C$500)=6)*(MONTH(Registres!C$2:C$500)=$C$2)*(YEAR(Registres!C$2:C$500)=$E$2)*(TEXT(Registres!F$2:F$500,"0")=TEXT($A12,"0")))>0,"✓",""),"") | J12: =IF(7<=DAY(EOMONTH(DATE($E$2,$C$2,1),0)),IF(SUMPRODUCT((DAY(Registres!C$2:C$500)=7)*(MONTH(Registres!C$2:C$500)=$C$2)*(YEAR(Registres!C$2:C$500)=$E$2)*(TEXT(Registres!F$2:F$500,"0")=TEXT($A12,"0")))>0,"✓",""),"") | K12: =IF(8<=DAY(EOMONTH(DATE($E$2,$C$2,1),0)),IF(SUMPRODUCT((DAY(Registres!C$2:C$500)=8)*(MONTH(Registres!C$2:C$500)=$C$2)*(YEAR(Registres!C$2:C$500)=$E$2)*(TEXT(Registres!F$2:F$500,"0")=TEXT($A12,"0")))>0,"✓",""),"") | L12: =IF(9<=DAY(EOMONTH(DATE($E$2,$C$2,1),0)),IF(SUMPRODUCT((DAY(Registres!C$2:C$500)=9)*(MONTH(Registres!C$2:C$500)=$C$2)*(YEAR(Registres!C$2:C$500)=$E$2)*(TEXT(Registres!F$2:F$500,"0")=TEXT($A12,"0")))>0,"✓",""),"") | M12: =IF(10<=DAY(EOMONTH(DATE($E$2,$C$2,1),0)),IF(SUMPRODUCT((DAY(Registres!C$2:C$500)=10)*(MONTH(Registres!C$2:C$500)=$C$2)*(YEAR(Registres!C$2:C$500)=$E$2)*(TEXT(Registres!F$2:F$500,"0")=TEXT($A12,"0")))>0,"✓",""),"") | N12: =IF(11<=DAY(EOMONTH(DATE($E$2,$C$2,1),0)),IF(SUMPRODUCT((DAY(Registres!C$2:C$500)=11)*(MONTH(Registres!C$2:C$500)=$C$2)*(YEAR(Registres!C$2:C$500)=$E$2)*(TEXT(Registres!F$2:F$500,"0")=TEXT($A12,"0")))>0,"✓",""),"") | O12: =IF(12<=DAY(EOMONTH(DATE($E$2,$C$2,1),0)),IF(SUMPRODUCT((DAY(Registres!C$2:C$500)=12)*(MONTH(Registres!C$2:C$500)=$C$2)*(YEAR(Registres!C$2:C$500)=$E$2)*(TEXT(Registres!F$2:F$500,"0")=TEXT($A12,"0")))>0,"✓",""),"") | P12: =IF(13<=DAY(EOMONTH(DATE($E$2,$C$2,1),0)),IF(SUMPRODUCT((DAY(Registres!C$2:C$500)=13)*(MONTH(Registres!C$2:C$500)=$C$2)*(YEAR(Registres!C$2:C$500)=$E$2)*(TEXT(Registres!F$2:F$500,"0")=TEXT($A12,"0")))>0,"✓",""),"") | Q12: =IF(14<=DAY(EOMONTH(DATE($E$2,$C$2,1),0)),IF(SUMPRODUCT((DAY(Registres!C$2:C$500)=14)*(MONTH(Registres!C$2:C$500)=$C$2)*(YEAR(Registres!C$2:C$500)=$E$2)*(TEXT(Registres!F$2:F$500,"0")=TEXT($A12,"0")))>0,"✓",""),"") | R12: =IF(15<=DAY(EOMONTH(DATE($E$2,$C$2,1),0)),IF(SUMPRODUCT((DAY(Registres!C$2:C$500)=15)*(MONTH(Registres!C$2:C$500)=$C$2)*(YEAR(Registres!C$2:C$500)=$E$2)*(TEXT(Registres!F$2:F$500,"0")=TEXT($A12,"0")))>0,"✓",""),"") | S12: =IF(16<=DAY(EOMONTH(DATE($E$2,$C$2,1),0)),IF(SUMPRODUCT((DAY(Registres!C$2:C$500)=16)*(MONTH(Registres!C$2:C$500)=$C$2)*(YEAR(Registres!C$2:C$500)=$E$2)*(TEXT(Registres!F$2:F$500,"0")=TEXT($A12,"0")))>0,"✓",""),"") | T12: =IF(17<=DAY(EOMONTH(DATE($E$2,$C$2,1),0)),IF(SUMPRODUCT((DAY(Registres!C$2:C$500)=17)*(MONTH(Registres!C$2:C$500)=$C$2)*(YEAR(Registres!C$2:C$500)=$E$2)*(TEXT(Registres!F$2:F$500,"0")=TEXT($A12,"0")))>0,"✓",""),"") | U12: =IF(18<=DAY(EOMONTH(DATE($E$2,$C$2,1),0)),IF(SUMPRODUCT((DAY(Registres!C$2:C$500)=18)*(MONTH(Registres!C$2:C$500)=$C$2)*(YEAR(Registres!C$2:C$500)=$E$2)*(TEXT(Registres!F$2:F$500,"0")=TEXT($A12,"0")))>0,"✓",""),"") | V12: =IF(19<=DAY(EOMONTH(DATE($E$2,$C$2,1),0)),IF(SUMPRODUCT((DAY(Registres!C$2:C$500)=19)*(MONTH(Registres!C$2:C$500)=$C$2)*(YEAR(Registres!C$2:C$500)=$E$2)*(TEXT(Registres!F$2:F$500,"0")=TEXT($A12,"0")))>0,"✓",""),"") | W12: =IF(20<=DAY(EOMONTH(DATE($E$2,$C$2,1),0)),IF(SUMPRODUCT((DAY(Registres!C$2:C$500)=20)*(MONTH(Registres!C$2:C$500)=$C$2)*(YEAR(Registres!C$2:C$500)=$E$2)*(TEXT(Registres!F$2:F$500,"0")=TEXT($A12,"0")))>0,"✓",""),"") | X12: =IF(21<=DAY(EOMONTH(DATE($E$2,$C$2,1),0)),IF(SUMPRODUCT((DAY(Registres!C$2:C$500)=21)*(MONTH(Registres!C$2:C$500)=$C$2)*(YEAR(Registres!C$2:C$500)=$E$2)*(TEXT(Registres!F$2:F$500,"0")=TEXT($A12,"0")))>0,"✓",""),"") | Y12: =IF(22<=DAY(EOMONTH(DATE($E$2,$C$2,1),0)),IF(SUMPRODUCT((DAY(Registres!C$2:C$500)=22)*(MONTH(Registres!C$2:C$500)=$C$2)*(YEAR(Registres!C$2:C$500)=$E$2)*(TEXT(Registres!F$2:F$500,"0")=TEXT($A12,"0")))>0,"✓",""),"") | Z12: =IF(23<=DAY(EOMONTH(DATE($E$2,$C$2,1),0)),IF(SUMPRODUCT((DAY(Registres!C$2:C$500)=23)*(MONTH(Registres!C$2:C$500)=$C$2)*(YEAR(Registres!C$2:C$500)=$E$2)*(TEXT(Registres!F$2:F$500,"0")=TEXT($A12,"0")))>0,"✓",""),"") | AA12: =IF(24<=DAY(EOMONTH(DATE($E$2,$C$2,1),0)),IF(SUMPRODUCT((DAY(Registres!C$2:C$500)=24)*(MONTH(Registres!C$2:C$500)=$C$2)*(YEAR(Registres!C$2:C$500)=$E$2)*(TEXT(Registres!F$2:F$500,"0")=TEXT($A12,"0")))>0,"✓",""),"") | AB12: =IF(25<=DAY(EOMONTH(DATE($E$2,$C$2,1),0)),IF(SUMPRODUCT((DAY(Registres!C$2:C$500)=25)*(MONTH(Registres!C$2:C$500)=$C$2)*(YEAR(Registres!C$2:C$500)=$E$2)*(TEXT(Registres!F$2:F$500,"0")=TEXT($A12,"0")))>0,"✓",""),"") | AC12: =IF(26<=DAY(EOMONTH(DATE($E$2,$C$2,1),0)),IF(SUMPRODUCT((DAY(Registres!C$2:C$500)=26)*(MONTH(Registres!C$2:C$500)=$C$2)*(YEAR(Registres!C$2:C$500)=$E$2)*(TEXT(Registres!F$2:F$500,"0")=TEXT($A12,"0")))>0,"✓",""),"") | AD12: =IF(27<=DAY(EOMONTH(DATE($E$2,$C$2,1),0)),IF(SUMPRODUCT((DAY(Registres!C$2:C$500)=27)*(MONTH(Registres!C$2:C$500)=$C$2)*(YEAR(Registres!C$2:C$500)=$E$2)*(TEXT(Registres!F$2:F$500,"0")=TEXT($A12,"0")))>0,"✓",""),"") | AE12: =IF(28<=DAY(EOMONTH(DATE($E$2,$C$2,1),0)),IF(SUMPRODUCT((DAY(Registres!C$2:C$500)=28)*(MONTH(Registres!C$2:C$500)=$C$2)*(YEAR(Registres!C$2:C$500)=$E$2)*(TEXT(Registres!F$2:F$500,"0")=TEXT($A12,"0")))>0,"✓",""),"") | AF12: =IF(29<=DAY(EOMONTH(DATE($E$2,$C$2,1),0)),IF(SUMPRODUCT((DAY(Registres!C$2:C$500)=29)*(MONTH(Registres!C$2:C$500)=$C$2)*(YEAR(Registres!C$2:C$500)=$E$2)*(TEXT(Registres!F$2:F$500,"0")=TEXT($A12,"0")))>0,"✓",""),"") | AG12: =IF(30<=DAY(EOMONTH(DATE($E$2,$C$2,1),0)),IF(SUMPRODUCT((DAY(Registres!C$2:C$500)=30)*(MONTH(Registres!C$2:C$500)=$C$2)*(YEAR(Registres!C$2:C$500)=$E$2)*(TEXT(Registres!F$2:F$500,"0")=TEXT($A12,"0")))>0,"✓",""),"") | AH12: =IF(31<=DAY(EOMONTH(DATE($E$2,$C$2,1),0)),IF(SUMPRODUCT((DAY(Registres!C$2:C$500)=31)*(MONTH(Registres!C$2:C$500)=$C$2)*(YEAR(Registres!C$2:C$500)=$E$2)*(TEXT(Registres!F$2:F$500,"0")=TEXT($A12,"0")))>0,"✓",""),"") | AI12: =COUNTIF(D12:AH12,"✓") -> 0
